Workbook
Name convert: #REF!
Name convert: '[1]Scratch Sheet'!$B$159:$D$166
Name convert: #REF!
Name convert: '[1]Scratch Sheet'!$B$159:$D$166
Name convert: '[1]Scratch Sheet'!$B$159:$D$166
Name convert: #REF!
Name convert: '[1]Scratch Sheet'!$B$159:$D$166
Name convert: '[1]Scratch Sheet'!$B$159:$D$166
Name convert: '[1]Scratch Sheet'!$B$159:$D$166
Name convert: '[1]Scratch Sheet'!$B$159:$D$166
Name convert: '[1]Scratch Sheet'!$B$159:$D$166
Name convert: '[1]Scratch Sheet'!$B$159:$D$166
Name convert: '[2]Scratch Sheet'!$B$159:$D$166
Name convert: #REF!
Name convert: #REF!
Name goldlook: #REF!
Name goldlook: '[1]Scratch Sheet'!$B$62:$C$68
Name goldlook: #REF!
Name goldlook: '[1]Scratch Sheet'!$B$62:$C$68
Name goldlook: '[1]Scratch Sheet'!$B$62:$C$68
Name goldlook: #REF!
Name goldlook: '[1]Scratch Sheet'!$B$62:$C$68
Name goldlook: '[1]Scratch Sheet'!$B$62:$C$68
Name goldlook: '[1]Scratch Sheet'!$B$62:$C$68
Name goldlook: '[1]Scratch Sheet'!$B$62:$C$68
Name goldlook: '[1]Scratch Sheet'!$B$62:$C$68
Name goldlook: '[1]Scratch Sheet'!$B$62:$C$68
Name goldlook: '[2]Scratch Sheet'!$B$62:$C$68
Name goldlook: #REF!
Name goldlook: #REF!
Name goldlook2: #REF!
Name goldlook2: #REF!
Name goldlook2: #REF!
Name goldlook2: #REF!
Name goldlook2: #REF!
Name goldlook2: #REF!
Name goldlook2: #REF!
Name goldlook2: #REF!
Name goldlook2: #REF!
Name goldlook2: #REF!
Name goldlook2: #REF!
Name goldlook2: #REF!
Name grouplook: #REF!
Name grouplook: [3]Sheet1!$E$5:$F$52
Name grouplook: #REF!
Name grouplook: [3]Sheet1!$E$5:$F$52
Name grouplook: [3]Sheet1!$E$5:$F$52
Name grouplook: #REF!
Name grouplook: [3]Sheet1!$E$5:$F$52
Name grouplook: [3]Sheet1!$E$5:$F$52
Name grouplook: [3]Sheet1!$E$5:$F$52
Name grouplook: [3]Sheet1!$E$5:$F$52
Name grouplook: [3]Sheet1!$E$5:$F$52
Name grouplook: [3]Sheet1!$E$5:$F$52
Name grouplook: #REF!
Name grouplook: #REF!
Name platlook: #REF!
Name platlook: '[1]Scratch Sheet'!$B$56:$E$59
Name platlook: #REF!
Name platlook: '[1]Scratch Sheet'!$B$56:$E$59

Sheet CHICLETS MASTER S2
A1: 2026 NJO S2 | I1: 2026 NJO S2 | K1: 2026 NJO S2 | P1: 2026 NJO S2 | X1: 2026 NJO S2 | AR1: CUSTOM TIMES | AU1: 2026 NJO S2 | BA1: 2026 NJO S2
A2: THURSDAY JULY 23 | I2: THURSDAY JULY 23 | K2: THURSDAY JULY 23 | P2: THURSDAY JULY 23 | X2: THURSDAY JULY 23 | AC2: done by 4:30pm | AD2: start after 4pm | AE2: start after 10am | AF2: 11am-4pm YMCA | AR2: after 1pm | AS2: 7am-12pm 5pm-8pm | AU2: THURSDAY JULY 23 | BA2: THURSDAY JULY 23
B3: EL TORO HS 1 | C3: EL TORO HS 2 | D3: EL TORO HS 3 | E3: BECKMAN HS 2 | F3: CAPISTRANO VALLEY HS 2 | G3: TUSTIN HS 2 | H3: OCEAN VIEW HS 2 | J3: GOLDEN WEST COLLEGE 2 | L3: ALISO NIGUEL HS | M3: SAN CLEMENTE HS | N3: MISSION VIEJO HS | O3: LAGUNA HILLS HS | Q3: UC IRVINE 1 | R3: UC IRVINE 2 | S3: EL MODENA HS | T3: GARDEN GROVE HS | U3: PORTOLA HS 2 | V3: VILLA PARK HS | W3: TRABUCO HILLS HS | Y3: SADDLEBACK COLLEGE 2 | Z3: FULLERTON HS | AA3: BREA OLINDA HS | AB3: ESPERANZA HS | AC3: OCEAN VIEW HS 1 | AD3: NEWPORT HARBOR HS | AE3: ORANGE COAST COLLEGE 1 | AF3: YORBA LINDA HS | AG3: GOLDEN WEST COLLEGE 1 | AH3: TROY HS | AI3: VALLEY HS (SA) | AJ3: SUNNY HILLS HS | AK3: CAPISTRANO VALLEY HS 1 | AL3: BECKMAN HS 1 | AM3: TUSTIN HS 1 | AN3: SAN JUAN HILLS HS | AO3: PORTOLA HS 1 | AP3: EDISON HS | AQ3: LONG BEACH CC 2 | AR3: SADDLEBACK COLLEGE 1 | AS3: ANAHEIM HS | AT3: LA SERNA HS | AV3: FULLERTON COLLEGE | AW3: LONG BEACH CC 1 | AX3: SERVITE HS | AY3: SONORA HS | AZ3: LA HABRA HS | BB3: NORTHWOOD HS | BC3: JSERRA CHS | BD3: CHAPMAN UNIVERSITY | BE3: WESTMINSTER HS | BF3: MARINA HS | BI3: =COUNTA(B3:BG3) -> 51
A4: 0.29166667 | B4: ='10U_M_Champ_35'!L56&"-"&'10U_M_Champ_35'!C56&"-"&TEXT('10U_M_Champ_35'!B56,"h:mm am/pm") -> 10B-003-Group I-7:00 AM | C4: ='10U_M_Champ_35'!L16&"-"&'10U_M_Champ_35'!C16&"-"&TEXT('10U_M_Champ_35'!B16,"h:mm am/pm") -> 10B-001-Group A-7:00 AM | D4: ='10U_M_Champ_35'!L36&"-"&'10U_M_Champ_35'!C36&"-"&TEXT('10U_M_Champ_35'!B36,"h:mm am/pm") -> 10B-002-Group H-7:00 AM | E4: ='12U_M_Classic_53'!L68&"-"&'12U_M_Classic_53'!C68&"-"&TEXT('12U_M_Classic_53'!B68,"h:mm am/pm") -> 12BX-002-Group-7:00 AM | F4: ='12U_M_Classic_53'!L88&"-"&'12U_M_Classic_53'!C88&"-"&TEXT('12U_M_Classic_53'!B88,"h:mm am/pm") -> 12BX-003-Group-7:00 AM | G4: ='12U_M_Classic_53'!L108&"-"&'12U_M_Classic_53'!C108&"-"&TEXT('12U_M_Classic_53'!B108,"h:mm am/pm") -> 12BX-013-Group-7:00 AM | H4: ='12U_M_Classic_53'!L29&"-"&'12U_M_Classic_53'!C29&"-"&TEXT('12U_M_Classic_53'!B29,"h:mm am/pm") -> 12BX-005-Group-7:00 AM | I4: 0.29166667 | J4: ='12U_M_Classic_53'!L48&"-"&'12U_M_Classic_53'!C48&"-"&TEXT('12U_M_Classic_53'!B48,"h:mm am/pm") -> 12BX-001-Group-7:00 AM | K4: 0.29166667 | L4: ='12U_M_Champ'!L18&"-"&'12U_M_Champ'!C18&"-"&TEXT('12U_M_Champ'!B18,"h:mm am/pm") -> 12B-001-Group-7:00 AM | M4: ='12U_M_Champ'!L37&"-"&'12U_M_Champ'!C37&"-"&TEXT('12U_M_Champ'!B37,"h:mm am/pm") -> 12B-002-Group-7:00 AM | N4: ='12U_M_Champ'!L56&"-"&'12U_M_Champ'!C56&"-"&TEXT('12U_M_Champ'!B56,"h:mm am/pm") -> 12B-003-Group-7:00 AM | O4: ='12U_M_Champ'!L75&"-"&'12U_M_Champ'!C75&"-"&TEXT('12U_M_Champ'!B75,"h:mm am/pm") -> 12B-004-Group-7:00 AM | P4: 0.29166667 | Q4: ='14U_M_Champ'!L18&"-"&'14U_M_Champ'!C18&"-"&TEXT('14U_M_Champ'!B18,"h:mm am/pm") -> 14B-001-Group-7:00 AM | R4: ='14U_M_Champ'!L37&"-"&'14U_M_Champ'!C37&"-"&TEXT('14U_M_Champ'!B37,"h:mm am/pm") -> 14B-002-Group-7:00 AM | S4: ='14U_M_Champ'!L56&"-"&'14U_M_Champ'!C56&"-"&TEXT('14U_M_Champ'!B56,"h:mm am/pm") -> 14B-003-Group-7:00 AM | T4: ='14U_M_Champ'!L75&"-"&'14U_M_Champ'!C75&"-"&TEXT('14U_M_Champ'!B75,"h:mm am/pm") -> 14B-004-Group-7:00 AM | U4: ='14U_M_Invite_36'!L56&"-"&'14U_M_Invite_36'!C56&"-"&TEXT('14U_M_Invite_36'!B56,"h:mm am/pm") -> 14BQ-003-Group I-7:00 AM | V4: ='14U_M_Invite_36'!L36&"-"&'14U_M_Invite_36'!C36&"-"&TEXT('14U_M_Invite_36'!B36,"h:mm am/pm") -> 14BQ-002-Group H-7:00 AM | W4: ='14U_M_Invite_36'!L16&"-"&'14U_M_Invite_36'!C16&"-"&TEXT('14U_M_Invite_36'!B16,"h:mm am/pm") -> 14BQ-001-Group A-7:00 AM | X4: 0.29166667 | Z4: ='16U_M_Invite'!L83&"-"&'16U_M_Invite'!C83&"-"&TEXT('16U_M_Invite'!B83,"h:mm am/pm") -> 16BQ-004-Group-7:00 AM | AA4: ='14U_M_Classic'!L18&"-"&'14U_M_Classic'!C18&"-"&TEXT('14U_M_Classic'!B18,"h:mm am/pm") -> 14BX-004-Group-7:00 AM | AB4: ='14U_M_Classic'!L56&"-"&'14U_M_Classic'!C56&"-"&TEXT('14U_M_Classic'!B56,"h:mm am/pm") -> 14BX-002-Group-7:00 AM | AC4: ='14U_M_Classic'!L78&"-"&'14U_M_Classic'!C78&"-"&TEXT('14U_M_Classic'!B78,"h:mm am/pm") -> 14BX-001-Group-7:00 AM | AF4: ='16U_M_Invite'!L18&"-"&'16U_M_Invite'!C18&"-"&TEXT('16U_M_Invite'!B18,"h:mm am/pm") -> 16BQ-001-Group-7:00 AM | AG4: ='18U_M_Classic'!L75&"-"&'18U_M_Classic'!C75&"-"&TEXT('18U_M_Classic'!B75,"h:mm am/pm") -> 18BX-004-Group-7:00 AM | AH4: ='18U_M_Classic'!L37&"-"&'18U_M_Classic'!C37&"-"&TEXT('18U_M_Classic'!B37,"h:mm am/pm") -> 18BX-002-Group-7:00 AM | AI4: ='18U_M_Classic'!L56&"-"&'18U_M_Classic'!C56&"-"&TEXT('18U_M_Classic'!B56,"h:mm am/pm") -> 18BX-003-Group-7:00 AM | AJ4: ='18U_M_Classic'!L18&"-"&'18U_M_Classic'!C18&"-"&TEXT('18U_M_Classic'!B18,"h:mm am/pm") -> 18BX-001-Group-7:00 AM | AK4: ='16U_M_Invite'!L45&"-"&'16U_M_Invite'!C45&"-"&TEXT('16U_M_Invite'!B45,"h:mm am/pm") -> 16BQ-002-Group-7:00 AM | AL4: ='14U_M_Classic'!L37&"-"&'14U_M_Classic'!C37&"-"&TEXT('14U_M_Classic'!B37,"h:mm am/pm") -> 14BX-003-Group-7:00 AM | AM4: ='16U_M_Invite'!L64&"-"&'16U_M_Invite'!C64&"-"&TEXT('16U_M_Invite'!B64,"h:mm am/pm") -> 16BQ-003-Group-7:00 AM | AN4: ='16U_M_Classic'!L56&"-"&'16U_M_Classic'!C56&"-"&TEXT('16U_M_Classic'!B56,"h:mm am/pm") -> 16BX-003-Group-7:00 AM | AO4: ='16U_M_Classic'!L75&"-"&'16U_M_Classic'!C75&"-"&TEXT('16U_M_Classic'!B75,"h:mm am/pm") -> 16BX-004-Group-7:00 AM | AP4: ='16U_M_Classic'!L18&"-"&'16U_M_Classic'!C18&"-"&TEXT('16U_M_Classic'!B18,"h:mm am/pm") -> 16BX-001-Group-7:00 AM | AQ4: ='16U_M_Classic'!L37&"-"&'16U_M_Classic'!C37&"-"&TEXT('16U_M_Classic'!B37,"h:mm am/pm") -> 16BX-002-Group-7:00 AM | AS4: ='18U_M_INVITE_NEW_23'!L36&"-"&'18U_M_INVITE_NEW_23'!C36&"-"&TEXT('18U_M_INVITE_NEW_23'!B36,"h:mm am/pm") -> 18BQ-002-Group-7:00 AM | AT4: ='18U_M_INVITE_NEW_23'!L17&"-"&'18U_M_INVITE_NEW_23'!C17&"-"&TEXT('18U_M_INVITE_NEW_23'!B17,"h:mm am/pm") -> 18BQ-001-Group-7:00 AM | AU4: 0.29166667 | AV4: ='16U_M_Champ'!L18&"-"&'16U_M_Champ'!C18&"-"&TEXT('16U_M_Champ'!B18,"h:mm am/pm") -> 16B-001-Group-7:00 AM | AW4: ='16U_M_Champ'!L37&"-"&'16U_M_Champ'!C37&"-"&TEXT('16U_M_Champ'!B37,"h:mm am/pm") -> 16B-002-Group-7:00 AM | AX4: ='16U_M_Champ'!L56&"-"&'16U_M_Champ'!C56&"-"&TEXT('16U_M_Champ'!B56,"h:mm am/pm") -> 16B-003-Group-7:00 AM | AY4: ='16U_M_Champ'!L75&"-"&'16U_M_Champ'!C75&"-"&TEXT('16U_M_Champ'!B75,"h:mm am/pm") -> 16B-004-Group-7:00 AM | BA4: 0.29166667 | BB4: ='18U_M_Champ'!L18&"-"&'18U_M_Champ'!C18&"-"&TEXT('18U_M_Champ'!B18,"h:mm am/pm") -> 18B-001-Group-7:00 AM | BC4: ='18U_M_Champ'!L66&"-"&'18U_M_Champ'!C66&"-"&TEXT('18U_M_Champ'!B66,"h:mm am/pm") -> 18B-003-Group-7:00 AM | BD4: ='18U_M_Champ'!L34&"-"&'18U_M_Champ'!C34&"-"&TEXT('18U_M_Champ'!B34,"h:mm am/pm") -> 18B-002-Group-7:00 AM | BE4: ='18U_M_Champ'!L50&"-"&'18U_M_Champ'!C50&"-"&TEXT('18U_M_Champ'!B50,"h:mm am/pm") -> 18B-004-Group-7:00 AM | BF4: ='18U_M_Champ'!L82&"-"&'18U_M_Champ'!C82&"-"&TEXT('18U_M_Champ'!B82,"h:mm am/pm") -> 18B-005-Group-7:00 AM
A5: 0.32638889 | B5: ='10U_M_Champ_35'!L57&"-"&'10U_M_Champ_35'!C57&"-"&TEXT('10U_M_Champ_35'!B57,"h:mm am/pm") -> 10B-006-Group J-7:50 AM | C5: ='10U_M_Champ_35'!L17&"-"&'10U_M_Champ_35'!C17&"-"&TEXT('10U_M_Champ_35'!B17,"h:mm am/pm") -> 10B-004-Group B-7:50 AM | D5: ='10U_M_Champ_35'!L37&"-"&'10U_M_Champ_35'!C37&"-"&TEXT('10U_M_Champ_35'!B37,"h:mm am/pm") -> 10B-005-Group G-7:50 AM | E5: ='12U_M_Classic_53'!L69&"-"&'12U_M_Classic_53'!C69&"-"&TEXT('12U_M_Classic_53'!B69,"h:mm am/pm") -> 12BX-007-Group-7:50 AM | F5: ='12U_M_Classic_53'!L89&"-"&'12U_M_Classic_53'!C89&"-"&TEXT('12U_M_Classic_53'!B89,"h:mm am/pm") -> 12BX-008-Group-7:50 AM | G5: ='12U_M_Classic_53'!L109&"-"&'12U_M_Classic_53'!C109&"-"&TEXT('12U_M_Classic_53'!B109,"h:mm am/pm") -> 12BX-13A-Group-7:50 AM | H5: ='12U_M_Classic_53'!L30&"-"&'12U_M_Classic_53'!C30&"-"&TEXT('12U_M_Classic_53'!B30,"h:mm am/pm") -> 12BX-5A-Group-7:50 AM | I5: 0.32638889 | J5: ='12U_M_Classic_53'!L49&"-"&'12U_M_Classic_53'!C49&"-"&TEXT('12U_M_Classic_53'!B49,"h:mm am/pm") -> 12BX-006-Group-7:50 AM | K5: 0.32638889 | L5: ='12U_M_Champ'!L19&"-"&'12U_M_Champ'!C19&"-"&TEXT('12U_M_Champ'!B19,"h:mm am/pm") -> 12B-005-Group-7:50 AM | M5: ='12U_M_Champ'!L38&"-"&'12U_M_Champ'!C38&"-"&TEXT('12U_M_Champ'!B38,"h:mm am/pm") -> 12B-006-Group-7:50 AM | N5: ='12U_M_Champ'!L57&"-"&'12U_M_Champ'!C57&"-"&TEXT('12U_M_Champ'!B57,"h:mm am/pm") -> 12B-007-Group-7:50 AM | O5: ='12U_M_Champ'!L76&"-"&'12U_M_Champ'!C76&"-"&TEXT('12U_M_Champ'!B76,"h:mm am/pm") -> 12B-008-Group-7:50 AM | P5: 0.32638889 | Q5: ='14U_M_Champ'!L19&"-"&'14U_M_Champ'!C19&"-"&TEXT('14U_M_Champ'!B19,"h:mm am/pm") -> 14B-005-Group-7:50 AM | R5: ='14U_M_Champ'!L38&"-"&'14U_M_Champ'!C38&"-"&TEXT('14U_M_Champ'!B38,"h:mm am/pm") -> 14B-006-Group-7:50 AM | S5: ='14U_M_Champ'!L57&"-"&'14U_M_Champ'!C57&"-"&TEXT('14U_M_Champ'!B57,"h:mm am/pm") -> 14B-007-Group-7:50 AM | T5: ='14U_M_Champ'!L76&"-"&'14U_M_Champ'!C76&"-"&TEXT('14U_M_Champ'!B76,"h:mm am/pm") -> 14B-008-Group-7:50 AM | U5: ='14U_M_Invite_36'!L57&"-"&'14U_M_Invite_36'!C57&"-"&TEXT('14U_M_Invite_36'!B57,"h:mm am/pm") -> 14BQ-006-Group J-7:50 AM | V5: ='14U_M_Invite_36'!L37&"-"&'14U_M_Invite_36'!C37&"-"&TEXT('14U_M_Invite_36'!B37,"h:mm am/pm") -> 14BQ-005-Group G-7:50 AM | W5: ='14U_M_Invite_36'!L17&"-"&'14U_M_Invite_36'!C17&"-"&TEXT('14U_M_Invite_36'!B17,"h:mm am/pm") -> 14BQ-004-Group B-7:50 AM | X5: 0.32638889 | Z5: ='16U_M_Invite'!L84&"-"&'16U_M_Invite'!C84&"-"&TEXT('16U_M_Invite'!B84,"h:mm am/pm") -> 16BQ-008-Group-7:50 AM | AA5: ='14U_M_Classic'!L19&"-"&'14U_M_Classic'!C19&"-"&TEXT('14U_M_Classic'!B19,"h:mm am/pm") -> 14BX-008-Group-7:50 AM | AB5: ='14U_M_Classic'!L57&"-"&'14U_M_Classic'!C57&"-"&TEXT('14U_M_Classic'!B57,"h:mm am/pm") -> 14BX-006-Group-7:50 AM | AC5: ='14U_M_Classic'!L79&"-"&'14U_M_Classic'!C79&"-"&TEXT('14U_M_Classic'!B79,"h:mm am/pm") -> 14BX-005-Group-7:50 AM | AF5: ='16U_M_Invite'!L19&"-"&'16U_M_Invite'!C19&"-"&TEXT('16U_M_Invite'!B19,"h:mm am/pm") -> 16BQ-005-Group-7:50 AM | AG5: ='18U_M_Classic'!L76&"-"&'18U_M_Classic'!C76&"-"&TEXT('18U_M_Classic'!B76,"h:mm am/pm") -> 18BX-008-Group-7:50 AM | AH5: ='18U_M_Classic'!L38&"-"&'18U_M_Classic'!C38&"-"&TEXT('18U_M_Classic'!B38,"h:mm am/pm") -> 18BX-006-Group-7:50 AM | AI5: ='18U_M_Classic'!L57&"-"&'18U_M_Classic'!C57&"-"&TEXT('18U_M_Classic'!B57,"h:mm am/pm") -> 18BX-007-Group-7:50 AM | AJ5: ='18U_M_Classic'!L19&"-"&'18U_M_Classic'!C19&"-"&TEXT('18U_M_Classic'!B19,"h:mm am/pm") -> 18BX-005-Group-7:50 AM | AK5: ='16U_M_Invite'!L46&"-"&'16U_M_Invite'!C46&"-"&TEXT('16U_M_Invite'!B46,"h:mm am/pm") -> 16BQ-006-Group-7:50 AM | AL5: ='14U_M_Classic'!L38&"-"&'14U_M_Classic'!C38&"-"&TEXT('14U_M_Classic'!B38,"h:mm am/pm") -> 14BX-007-Group-7:50 AM | AM5: ='16U_M_Invite'!L65&"-"&'16U_M_Invite'!C65&"-"&TEXT('16U_M_Invite'!B65,"h:mm am/pm") -> 16BQ-007-Group-7:50 AM | AN5: ='16U_M_Classic'!L57&"-"&'16U_M_Classic'!C57&"-"&TEXT('16U_M_Classic'!B57,"h:mm am/pm") -> 16BX-007-Group-7:50 AM | AO5: ='16U_M_Classic'!L76&"-"&'16U_M_Classic'!C76&"-"&TEXT('16U_M_Classic'!B76,"h:mm am/pm") -> 16BX-008-Group-7:50 AM | AP5: ='16U_M_Classic'!L19&"-"&'16U_M_Classic'!C19&"-"&TEXT('16U_M_Classic'!B19,"h:mm am/pm") -> 16BX-005-Group-7:50 AM | AQ5: ='16U_M_Classic'!L38&"-"&'16U_M_Classic'!C38&"-"&TEXT('16U_M_Classic'!B38,"h:mm am/pm") -> 16BX-006-Group-7:50 AM | AS5: ='18U_M_INVITE_NEW_23'!L37&"-"&'18U_M_INVITE_NEW_23'!C37&"-"&TEXT('18U_M_INVITE_NEW_23'!B37,"h:mm am/pm") -> 18BQ-004-Group-7:50 AM | AT5: ='18U_M_INVITE_NEW_23'!L18&"-"&'18U_M_INVITE_NEW_23'!C18&"-"&TEXT('18U_M_INVITE_NEW_23'!B18,"h:mm am/pm") -> 18BQ-003-Group-7:50 AM | AU5: 0.32638889 | AV5: ='16U_M_Champ'!L19&"-"&'16U_M_Champ'!C19&"-"&TEXT('16U_M_Champ'!B19,"h:mm am/pm") -> 16B-005-Group-7:50 AM | AW5: ='16U_M_Champ'!L38&"-"&'16U_M_Champ'!C38&"-"&TEXT('16U_M_Champ'!B38,"h:mm am/pm") -> 16B-006-Group-7:50 AM | AX5: ='16U_M_Champ'!L57&"-"&'16U_M_Champ'!C57&"-"&TEXT('16U_M_Champ'!B57,"h:mm am/pm") -> 16B-007-Group-7:50 AM | AY5: ='16U_M_Champ'!L76&"-"&'16U_M_Champ'!C76&"-"&TEXT('16U_M_Champ'!B76,"h:mm am/pm") -> 16B-008-Group-7:50 AM | BA5: 0.33333333 | BB5: ='18U_M_Champ'!L19&"-"&'18U_M_Champ'!C19&"-"&TEXT('18U_M_Champ'!B19,"h:mm am/pm") -> 18B-006-Group-8:00 AM | BC5: ='18U_M_Champ'!L67&"-"&'18U_M_Champ'!C67&"-"&TEXT('18U_M_Champ'!B67,"h:mm am/pm") -> 18B-009-Group-8:00 AM | BD5: ='18U_M_Champ'!L35&"-"&'18U_M_Champ'!C35&"-"&TEXT('18U_M_Champ'!B35,"h:mm am/pm") -> 18B-007-Group-8:00 AM | BE5: ='18U_M_Champ'!L51&"-"&'18U_M_Champ'!C51&"-"&TEXT('18U_M_Champ'!B51,"h:mm am/pm") -> 18B-008-Group-8:00 AM | BF5: ='18U_M_Champ'!L83&"-"&'18U_M_Champ'!C83&"-"&TEXT('18U_M_Champ'!B83,"h:mm am/pm") -> 18B-010-Group-8:00 AM
A6: 0.36111111 | B6: ='10U_M_Champ_35'!L58&"-"&'10U_M_Champ_35'!C58&"-"&TEXT('10U_M_Champ_35'!B58,"h:mm am/pm") -> 10B-012-Group L-8:40 AM | C6: ='10U_M_Champ_35'!L18&"-"&'10U_M_Champ_35'!C18&"-"&TEXT('10U_M_Champ_35'!B18,"h:mm am/pm") -> 10B-007-Group C-8:40 AM | D6: ='10U_M_Champ_35'!L38&"-"&'10U_M_Champ_35'!C38&"-"&TEXT('10U_M_Champ_35'!B38,"h:mm am/pm") -> 10B-008-Group F-8:40 AM | E6: ='12U_M_Classic_53'!L70&"-"&'12U_M_Classic_53'!C70&"-"&TEXT('12U_M_Classic_53'!B70,"h:mm am/pm") -> 12BX-012-Group-8:40 AM | F6: ='12U_M_Classic_53'!L90&"-"&'12U_M_Classic_53'!C90&"-"&TEXT('12U_M_Classic_53'!B90,"h:mm am/pm") -> 12BX-017-Group-8:40 AM | G6: ='12U_M_Classic_53'!L110&"-"&'12U_M_Classic_53'!C110&"-"&TEXT('12U_M_Classic_53'!B110,"h:mm am/pm") -> 12BX-004-Group-8:40 AM | H6: ='12U_M_Classic_53'!L31&"-"&'12U_M_Classic_53'!C31&"-"&TEXT('12U_M_Classic_53'!B31,"h:mm am/pm") -> 12BX-010-Group-8:40 AM | I6: 0.36111111 | J6: ='12U_M_Classic_53'!L50&"-"&'12U_M_Classic_53'!C50&"-"&TEXT('12U_M_Classic_53'!B50,"h:mm am/pm") -> 12BX-011-Group-8:40 AM | K6: 0.36111111 | L6: ='12U_M_Champ'!L20&"-"&'12U_M_Champ'!C20&"-"&TEXT('12U_M_Champ'!B20,"h:mm am/pm") -> 12B-009-Group-8:40 AM | M6: ='12U_M_Champ'!L39&"-"&'12U_M_Champ'!C39&"-"&TEXT('12U_M_Champ'!B39,"h:mm am/pm") -> 12B-010-Group-8:40 AM | N6: ='12U_M_Champ'!L58&"-"&'12U_M_Champ'!C58&"-"&TEXT('12U_M_Champ'!B58,"h:mm am/pm") -> 12B-011-Group-8:40 AM | O6: ='12U_M_Champ'!L77&"-"&'12U_M_Champ'!C77&"-"&TEXT('12U_M_Champ'!B77,"h:mm am/pm") -> 12B-012-Group-8:40 AM | P6: 0.36111111 | Q6: ='14U_M_Champ'!L20&"-"&'14U_M_Champ'!C20&"-"&TEXT('14U_M_Champ'!B20,"h:mm am/pm") -> 14B-009-Group-8:40 AM | R6: ='14U_M_Champ'!L39&"-"&'14U_M_Champ'!C39&"-"&TEXT('14U_M_Champ'!B39,"h:mm am/pm") -> 14B-010-Group-8:40 AM | S6: ='14U_M_Champ'!L58&"-"&'14U_M_Champ'!C58&"-"&TEXT('14U_M_Champ'!B58,"h:mm am/pm") -> 14B-011-Group-8:40 AM | T6: ='14U_M_Champ'!L77&"-"&'14U_M_Champ'!C77&"-"&TEXT('14U_M_Champ'!B77,"h:mm am/pm") -> 14B-012-Group-8:40 AM | U6: ='14U_M_Invite_36'!L58&"-"&'14U_M_Invite_36'!C58&"-"&TEXT('14U_M_Invite_36'!B58,"h:mm am/pm") -> 14BQ-009-Group K-8:40 AM | V6: ='14U_M_Invite_36'!L38&"-"&'14U_M_Invite_36'!C38&"-"&TEXT('14U_M_Invite_36'!B38,"h:mm am/pm") -> 14BQ-008-Group F-8:40 AM | W6: ='14U_M_Invite_36'!L18&"-"&'14U_M_Invite_36'!C18&"-"&TEXT('14U_M_Invite_36'!B18,"h:mm am/pm") -> 14BQ-007-Group C-8:40 AM | X6: 0.36111111 | Z6: ='16U_M_Invite'!L85&"-"&'16U_M_Invite'!C85&"-"&TEXT('16U_M_Invite'!B85,"h:mm am/pm") -> 16BQ-012-Group-8:40 AM | AA6: ='14U_M_Classic'!L20&"-"&'14U_M_Classic'!C20&"-"&TEXT('14U_M_Classic'!B20,"h:mm am/pm") -> 14BX-012-Group-8:40 AM | AB6: ='14U_M_Classic'!L58&"-"&'14U_M_Classic'!C58&"-"&TEXT('14U_M_Classic'!B58,"h:mm am/pm") -> 14BX-010-Group-8:40 AM | AC6: ='14U_M_Classic'!L80&"-"&'14U_M_Classic'!C80&"-"&TEXT('14U_M_Classic'!B80,"h:mm am/pm") -> 14BX-009-Group-8:40 AM | AF6: ='16U_M_Invite'!L20&"-"&'16U_M_Invite'!C20&"-"&TEXT('16U_M_Invite'!B20,"h:mm am/pm") -> 16BQ-009-Group-8:40 AM | AG6: ='18U_M_Classic'!L77&"-"&'18U_M_Classic'!C77&"-"&TEXT('18U_M_Classic'!B77,"h:mm am/pm") -> 18BX-012-Group-8:40 AM | AH6: ='18U_M_Classic'!L39&"-"&'18U_M_Classic'!C39&"-"&TEXT('18U_M_Classic'!B39,"h:mm am/pm") -> 18BX-010-Group-8:40 AM | AI6: ='18U_M_Classic'!L58&"-"&'18U_M_Classic'!C58&"-"&TEXT('18U_M_Classic'!B58,"h:mm am/pm") -> 18BX-011-Group-8:40 AM | AJ6: ='18U_M_Classic'!L20&"-"&'18U_M_Classic'!C20&"-"&TEXT('18U_M_Classic'!B20,"h:mm am/pm") -> 18BX-009-Group-8:40 AM | AK6: ='16U_M_Invite'!L47&"-"&'16U_M_Invite'!C47&"-"&TEXT('16U_M_Invite'!B47,"h:mm am/pm") -> 16BQ-010-Group-8:40 AM | AL6: ='14U_M_Classic'!L39&"-"&'14U_M_Classic'!C39&"-"&TEXT('14U_M_Classic'!B39,"h:mm am/pm") -> 14BX-011-Group-8:40 AM | AM6: ='16U_M_Invite'!L66&"-"&'16U_M_Invite'!C66&"-"&TEXT('16U_M_Invite'!B66,"h:mm am/pm") -> 16BQ-011-Group-8:40 AM | AN6: ='16U_M_Classic'!L58&"-"&'16U_M_Classic'!C58&"-"&TEXT('16U_M_Classic'!B58,"h:mm am/pm") -> 16BX-011-Group-8:40 AM | AO6: ='16U_M_Classic'!L77&"-"&'16U_M_Classic'!C77&"-"&TEXT('16U_M_Classic'!B77,"h:mm am/pm") -> 16BX-012-Group-8:40 AM | AP6: ='16U_M_Classic'!L20&"-"&'16U_M_Classic'!C20&"-"&TEXT('16U_M_Classic'!B20,"h:mm am/pm") -> 16BX-009-Group-8:40 AM | AQ6: ='16U_M_Classic'!L39&"-"&'16U_M_Classic'!C39&"-"&TEXT('16U_M_Classic'!B39,"h:mm am/pm") -> 16BX-010-Group-8:40 AM | AS6: ='18U_M_INVITE_NEW_23'!L38&"-"&'18U_M_INVITE_NEW_23'!C38&"-"&TEXT('18U_M_INVITE_NEW_23'!B38,"h:mm am/pm") -> 18BQ-006-Group-8:40 AM | AT6: ='18U_M_INVITE_NEW_23'!L19&"-"&'18U_M_INVITE_NEW_23'!C19&"-"&TEXT('18U_M_INVITE_NEW_23'!B19,"h:mm am/pm") -> 18BQ-005-Group-8:40 AM | AU6: 0.36111111 | AV6: ='16U_M_Champ'!L20&"-"&'16U_M_Champ'!C20&"-"&TEXT('16U_M_Champ'!B20,"h:mm am/pm") -> 16B-009-Group-8:40 AM | AW6: ='16U_M_Champ'!L39&"-"&'16U_M_Champ'!C39&"-"&TEXT('16U_M_Champ'!B39,"h:mm am/pm") -> 16B-010-Group-8:40 AM | AX6: ='16U_M_Champ'!L58&"-"&'16U_M_Champ'!C58&"-"&TEXT('16U_M_Champ'!B58,"h:mm am/pm") -> 16B-011-Group-8:40 AM | AY6: ='16U_M_Champ'!L77&"-"&'16U_M_Champ'!C77&"-"&TEXT('16U_M_Champ'!B77,"h:mm am/pm") -> 16B-012-Group-8:40 AM | BA6: 0.375 | BB6: ='18U_M_Champ'!L20&"-"&'18U_M_Champ'!C20&"-"&TEXT('18U_M_Champ'!B20,"h:mm am/pm") -> 18B-011-Group-9:00 AM | BC6: ='18U_M_Champ'!L68&"-"&'18U_M_Champ'!C68&"-"&TEXT('18U_M_Champ'!B68,"h:mm am/pm") -> 18B-014-Group-9:00 AM | BD6: ='18U_M_Champ'!L36&"-"&'18U_M_Champ'!C36&"-"&TEXT('18U_M_Champ'!B36,"h:mm am/pm") -> 18B-012-Group-9:00 AM | BE6: ='18U_M_Champ'!L52&"-"&'18U_M_Champ'!C52&"-"&TEXT('18U_M_Champ'!B52,"h:mm am/pm") -> 18B-013-Group-9:00 AM | BF6: ='18U_M_Champ'!L84&"-"&'18U_M_Champ'!C84&"-"&TEXT('18U_M_Champ'!B84,"h:mm am/pm") -> 18B-015-Group-9:00 AM
A7: 0.39583333 | B7: ='10U_M_Champ_35'!L59&"-"&'10U_M_Champ_35'!C59&"-"&TEXT('10U_M_Champ_35'!B59,"h:mm am/pm") -> 10B-015-Group I-9:30 AM | C7: ='10U_M_Champ_35'!L19&"-"&'10U_M_Champ_35'!C19&"-"&TEXT('10U_M_Champ_35'!B19,"h:mm am/pm") -> 10B-010-Group D-9:30 AM | D7: ='10U_M_Champ_35'!L39&"-"&'10U_M_Champ_35'!C39&"-"&TEXT('10U_M_Champ_35'!B39,"h:mm am/pm") -> 10B-011-Group E-9:30 AM | E7: ='12U_M_Classic_53'!L71&"-"&'12U_M_Classic_53'!C71&"-"&TEXT('12U_M_Classic_53'!B71,"h:mm am/pm") -> 12BX-016-Group-9:30 AM | F7: ='12U_M_Classic_53'!L91&"-"&'12U_M_Classic_53'!C91&"-"&TEXT('12U_M_Classic_53'!B91,"h:mm am/pm") -> 12BX-022-Group-9:30 AM | G7: ='12U_M_Classic_53'!L111&"-"&'12U_M_Classic_53'!C111&"-"&TEXT('12U_M_Classic_53'!B111,"h:mm am/pm") -> 12BX-009-Group-9:30 AM | H7: ='12U_M_Classic_53'!L32&"-"&'12U_M_Classic_53'!C32&"-"&TEXT('12U_M_Classic_53'!B32,"h:mm am/pm") -> 12BX-015-Group-9:30 AM | I7: 0.39583333 | J7: ='12U_M_Classic_53'!L51&"-"&'12U_M_Classic_53'!C51&"-"&TEXT('12U_M_Classic_53'!B51,"h:mm am/pm") -> 12BX-019-Group-9:30 AM | K7: 0.39583333 | L7: ='12U_M_Champ'!L21&"-"&'12U_M_Champ'!C21&"-"&TEXT('12U_M_Champ'!B21,"h:mm am/pm") -> 12B-013-Group-9:30 AM | M7: ='12U_M_Champ'!L40&"-"&'12U_M_Champ'!C40&"-"&TEXT('12U_M_Champ'!B40,"h:mm am/pm") -> 12B-014-Group-9:30 AM | N7: ='12U_M_Champ'!L59&"-"&'12U_M_Champ'!C59&"-"&TEXT('12U_M_Champ'!B59,"h:mm am/pm") -> 12B-015-Group-9:30 AM | O7: ='12U_M_Champ'!L78&"-"&'12U_M_Champ'!C78&"-"&TEXT('12U_M_Champ'!B78,"h:mm am/pm") -> 12B-016-Group-9:30 AM | P7: 0.39583333 | Q7: ='14U_M_Champ'!L21&"-"&'14U_M_Champ'!C21&"-"&TEXT('14U_M_Champ'!B21,"h:mm am/pm") -> 14B-013-Group-9:30 AM | R7: ='14U_M_Champ'!L40&"-"&'14U_M_Champ'!C40&"-"&TEXT('14U_M_Champ'!B40,"h:mm am/pm") -> 14B-014-Group-9:30 AM | S7: ='14U_M_Champ'!L59&"-"&'14U_M_Champ'!C59&"-"&TEXT('14U_M_Champ'!B59,"h:mm am/pm") -> 14B-015-Group-9:30 AM | T7: ='14U_M_Champ'!L78&"-"&'14U_M_Champ'!C78&"-"&TEXT('14U_M_Champ'!B78,"h:mm am/pm") -> 14B-016-Group-9:30 AM | U7: ='14U_M_Invite_36'!L59&"-"&'14U_M_Invite_36'!C59&"-"&TEXT('14U_M_Invite_36'!B59,"h:mm am/pm") -> 14BQ-012-Group L-9:30 AM | V7: ='14U_M_Invite_36'!L39&"-"&'14U_M_Invite_36'!C39&"-"&TEXT('14U_M_Invite_36'!B39,"h:mm am/pm") -> 14BQ-011-Group E-9:30 AM | W7: ='14U_M_Invite_36'!L19&"-"&'14U_M_Invite_36'!C19&"-"&TEXT('14U_M_Invite_36'!B19,"h:mm am/pm") -> 14BQ-010-Group D-9:30 AM | X7: 0.39583333 | Z7: ='16U_M_Invite'!L86&"-"&'16U_M_Invite'!C86&"-"&TEXT('16U_M_Invite'!B86,"h:mm am/pm") -> 16BQ-016-Group-9:30 AM | AA7: ='14U_M_Classic'!L21&"-"&'14U_M_Classic'!C21&"-"&TEXT('14U_M_Classic'!B21,"h:mm am/pm") -> 14BX-016-Group-9:30 AM | AB7: ='14U_M_Classic'!L59&"-"&'14U_M_Classic'!C59&"-"&TEXT('14U_M_Classic'!B59,"h:mm am/pm") -> 14BX-014-Group-9:30 AM | AC7: ='14U_M_Classic'!L81&"-"&'14U_M_Classic'!C81&"-"&TEXT('14U_M_Classic'!B81,"h:mm am/pm") -> 14BX-013-Group-9:30 AM | AF7: ='16U_M_Invite'!L21&"-"&'16U_M_Invite'!C21&"-"&TEXT('16U_M_Invite'!B21,"h:mm am/pm") -> 16BQ-013-Group-9:30 AM | AG7: ='18U_M_Classic'!L78&"-"&'18U_M_Classic'!C78&"-"&TEXT('18U_M_Classic'!B78,"h:mm am/pm") -> 18BX-016-Group-9:30 AM | AH7: ='18U_M_Classic'!L40&"-"&'18U_M_Classic'!C40&"-"&TEXT('18U_M_Classic'!B40,"h:mm am/pm") -> 18BX-014-Group-9:30 AM | AI7: ='18U_M_Classic'!L59&"-"&'18U_M_Classic'!C59&"-"&TEXT('18U_M_Classic'!B59,"h:mm am/pm") -> 18BX-015-Group-9:30 AM | AJ7: ='18U_M_Classic'!L21&"-"&'18U_M_Classic'!C21&"-"&TEXT('18U_M_Classic'!B21,"h:mm am/pm") -> 18BX-013-Group-9:30 AM | AK7: ='16U_M_Invite'!L48&"-"&'16U_M_Invite'!C48&"-"&TEXT('16U_M_Invite'!B48,"h:mm am/pm") -> 16BQ-014-Group-9:30 AM | AL7: ='14U_M_Classic'!L40&"-"&'14U_M_Classic'!C40&"-"&TEXT('14U_M_Classic'!B40,"h:mm am/pm") -> 14BX-015-Group-9:30 AM | AM7: ='16U_M_Invite'!L67&"-"&'16U_M_Invite'!C67&"-"&TEXT('16U_M_Invite'!B67,"h:mm am/pm") -> 16BQ-015-Group-9:30 AM | AN7: ='16U_M_Classic'!L59&"-"&'16U_M_Classic'!C59&"-"&TEXT('16U_M_Classic'!B59,"h:mm am/pm") -> 16BX-015-Group-9:30 AM | AO7: ='16U_M_Classic'!L78&"-"&'16U_M_Classic'!C78&"-"&TEXT('16U_M_Classic'!B78,"h:mm am/pm") -> 16BX-016-Group-9:30 AM | AP7: ='16U_M_Classic'!L21&"-"&'16U_M_Classic'!C21&"-"&TEXT('16U_M_Classic'!B21,"h:mm am/pm") -> 16BX-013-Group-9:30 AM | AQ7: ='16U_M_Classic'!L40&"-"&'16U_M_Classic'!C40&"-"&TEXT('16U_M_Classic'!B40,"h:mm am/pm") -> 16BX-014-Group-9:30 AM | AS7: ='18U_M_INVITE_NEW_23'!L39&"-"&'18U_M_INVITE_NEW_23'!C39&"-"&TEXT('18U_M_INVITE_NEW_23'!B39,"h:mm am/pm") -> 18BQ-008-Group-9:30 AM | AT7: ='18U_M_INVITE_NEW_23'!L20&"-"&'18U_M_INVITE_NEW_23'!C20&"-"&TEXT('18U_M_INVITE_NEW_23'!B20,"h:mm am/pm") -> 18BQ-007-Group-9:30 AM | AU7: 0.39583333 | AV7: ='16U_M_Champ'!L21&"-"&'16U_M_Champ'!C21&"-"&TEXT('16U_M_Champ'!B21,"h:mm am/pm") -> 16B-013-Group-9:30 AM | AW7: ='16U_M_Champ'!L40&"-"&'16U_M_Champ'!C40&"-"&TEXT('16U_M_Champ'!B40,"h:mm am/pm") -> 16B-014-Group-9:30 AM | AX7: ='16U_M_Champ'!L59&"-"&'16U_M_Champ'!C59&"-"&TEXT('16U_M_Champ'!B59,"h:mm am/pm") -> 16B-015-Group-9:30 AM | AY7: ='16U_M_Champ'!L78&"-"&'16U_M_Champ'!C78&"-"&TEXT('16U_M_Champ'!B78,"h:mm am/pm") -> 16B-016-Group-9:30 AM | BA7: 0.41666667 | BB7: ='18U_M_Champ'!L21&"-"&'18U_M_Champ'!C21&"-"&TEXT('18U_M_Champ'!B21,"h:mm am/pm") -> 18B-016-Group-10:00 AM | BC7: ='18U_M_Champ'!L69&"-"&'18U_M_Champ'!C69&"-"&TEXT('18U_M_Champ'!B69,"h:mm am/pm") -> 18B-019-Group-10:00 AM | BD7: ='18U_M_Champ'!L37&"-"&'18U_M_Champ'!C37&"-"&TEXT('18U_M_Champ'!B37,"h:mm am/pm") -> 18B-017-Group-10:00 AM | BE7: ='18U_M_Champ'!L53&"-"&'18U_M_Champ'!C53&"-"&TEXT('18U_M_Champ'!B53,"h:mm am/pm") -> 18B-018-Group-10:00 AM | BF7: ='18U_M_Champ'!L85&"-"&'18U_M_Champ'!C85&"-"&TEXT('18U_M_Champ'!B85,"h:mm am/pm") -> 18B-020-Group-10:00 AM
A8: 0.43055556 | B8: ='10U_M_Champ_35'!L60&"-"&'10U_M_Champ_35'!C60&"-"&TEXT('10U_M_Champ_35'!B60,"h:mm am/pm") -> 10B-018-Group J-10:20 AM | C8: ='10U_M_Champ_35'!L20&"-"&'10U_M_Champ_35'!C20&"-"&TEXT('10U_M_Champ_35'!B20,"h:mm am/pm") -> 10B-013-Group A-10:20 AM | D8: ='10U_M_Champ_35'!L40&"-"&'10U_M_Champ_35'!C40&"-"&TEXT('10U_M_Champ_35'!B40,"h:mm am/pm") -> 10B-014-Group H-10:20 AM | E8: ='12U_M_Classic_53'!L72&"-"&'12U_M_Classic_53'!C72&"-"&TEXT('12U_M_Classic_53'!B72,"h:mm am/pm") -> 12BX-021-Group-10:20 AM | F8: ='12U_M_Classic_53'!L92&"-"&'12U_M_Classic_53'!C92&"-"&TEXT('12U_M_Classic_53'!B92,"h:mm am/pm") -> 12BX-027-Group-10:20 AM | G8: ='12U_M_Classic_53'!L112&"-"&'12U_M_Classic_53'!C112&"-"&TEXT('12U_M_Classic_53'!B112,"h:mm am/pm") -> 12BX-014-Group-10:20 AM | H8: ='12U_M_Classic_53'!L33&"-"&'12U_M_Classic_53'!C33&"-"&TEXT('12U_M_Classic_53'!B33,"h:mm am/pm") -> 12BX-024-Group-10:20 AM | I8: 0.43055556 | J8: ='12U_M_Classic_53'!L52&"-"&'12U_M_Classic_53'!C52&"-"&TEXT('12U_M_Classic_53'!B52,"h:mm am/pm") -> 12BX-020-Group-10:20 AM | K8: 0.43055556 | L8: ='12U_M_Champ'!L22&"-"&'12U_M_Champ'!C22&"-"&TEXT('12U_M_Champ'!B22,"h:mm am/pm") -> 12B-017-Group-10:20 AM | M8: ='12U_M_Champ'!L41&"-"&'12U_M_Champ'!C41&"-"&TEXT('12U_M_Champ'!B41,"h:mm am/pm") -> 12B-018-Group-10:20 AM | N8: ='12U_M_Champ'!L60&"-"&'12U_M_Champ'!C60&"-"&TEXT('12U_M_Champ'!B60,"h:mm am/pm") -> 12B-019-Group-10:20 AM | O8: ='12U_M_Champ'!L79&"-"&'12U_M_Champ'!C79&"-"&TEXT('12U_M_Champ'!B79,"h:mm am/pm") -> 12B-020-Group-10:20 AM | P8: 0.43055556 | Q8: ='14U_M_Champ'!L22&"-"&'14U_M_Champ'!C22&"-"&TEXT('14U_M_Champ'!B22,"h:mm am/pm") -> 14B-017-Group-10:20 AM | R8: ='14U_M_Champ'!L41&"-"&'14U_M_Champ'!C41&"-"&TEXT('14U_M_Champ'!B41,"h:mm am/pm") -> 14B-018-Group-10:20 AM | S8: ='14U_M_Champ'!L60&"-"&'14U_M_Champ'!C60&"-"&TEXT('14U_M_Champ'!B60,"h:mm am/pm") -> 14B-019-Group-10:20 AM | T8: ='14U_M_Champ'!L79&"-"&'14U_M_Champ'!C79&"-"&TEXT('14U_M_Champ'!B79,"h:mm am/pm") -> 14B-020-Group-10:20 AM | U8: ='14U_M_Invite_36'!L60&"-"&'14U_M_Invite_36'!C60&"-"&TEXT('14U_M_Invite_36'!B60,"h:mm am/pm") -> 14BQ-015-Group I-10:20 AM | V8: ='14U_M_Invite_36'!L40&"-"&'14U_M_Invite_36'!C40&"-"&TEXT('14U_M_Invite_36'!B40,"h:mm am/pm") -> 14BQ-014-Group H-10:20 AM | W8: ='14U_M_Invite_36'!L20&"-"&'14U_M_Invite_36'!C20&"-"&TEXT('14U_M_Invite_36'!B20,"h:mm am/pm") -> 14BQ-013-Group A-10:20 AM | X8: 0.43055556 | Z8: ='16U_M_Invite'!L87&"-"&'16U_M_Invite'!C87&"-"&TEXT('16U_M_Invite'!B87,"h:mm am/pm") -> 16BQ-020-Group-10:20 AM | AA8: ='14U_M_Classic'!L22&"-"&'14U_M_Classic'!C22&"-"&TEXT('14U_M_Classic'!B22,"h:mm am/pm") -> 14BX-020-Group-10:20 AM | AB8: ='14U_M_Classic'!L60&"-"&'14U_M_Classic'!C60&"-"&TEXT('14U_M_Classic'!B60,"h:mm am/pm") -> 14BX-018-Group-10:20 AM | AC8: ='14U_M_Classic'!L82&"-"&'14U_M_Classic'!C82&"-"&TEXT('14U_M_Classic'!B82,"h:mm am/pm") -> 14BX-017-Group-10:20 AM | AG8: ='18U_M_Classic'!L79&"-"&'18U_M_Classic'!C79&"-"&TEXT('18U_M_Classic'!B79,"h:mm am/pm") -> 18BX-020-Group-10:20 AM | AH8: ='18U_M_Classic'!L41&"-"&'18U_M_Classic'!C41&"-"&TEXT('18U_M_Classic'!B41,"h:mm am/pm") -> 18BX-018-Group-10:20 AM | AI8: ='18U_M_Classic'!L60&"-"&'18U_M_Classic'!C60&"-"&TEXT('18U_M_Classic'!B60,"h:mm am/pm") -> 18BX-019-Group-10:20 AM | AJ8: ='18U_M_Classic'!L22&"-"&'18U_M_Classic'!C22&"-"&TEXT('18U_M_Classic'!B22,"h:mm am/pm") -> 18BX-017-Group-10:20 AM | AK8: ='16U_M_Invite'!L49&"-"&'16U_M_Invite'!C49&"-"&TEXT('16U_M_Invite'!B49,"h:mm am/pm") -> 16BQ-018-Group-10:20 AM | AL8: ='14U_M_Classic'!L41&"-"&'14U_M_Classic'!C41&"-"&TEXT('14U_M_Classic'!B41,"h:mm am/pm") -> 14BX-019-Group-10:20 AM | AM8: ='16U_M_Invite'!L68&"-"&'16U_M_Invite'!C68&"-"&TEXT('16U_M_Invite'!B68,"h:mm am/pm") -> 16BQ-019-Group-10:20 AM | AN8: ='16U_M_Classic'!L60&"-"&'16U_M_Classic'!C60&"-"&TEXT('16U_M_Classic'!B60,"h:mm am/pm") -> 16BX-019-Group-10:20 AM | AO8: ='16U_M_Classic'!L79&"-"&'16U_M_Classic'!C79&"-"&TEXT('16U_M_Classic'!B79,"h:mm am/pm") -> 16BX-020-Group-10:20 AM | AP8: ='16U_M_Classic'!L22&"-"&'16U_M_Classic'!C22&"-"&TEXT('16U_M_Classic'!B22,"h:mm am/pm") -> 16BX-017-Group-10:20 AM | AQ8: ='16U_M_Classic'!L41&"-"&'16U_M_Classic'!C41&"-"&TEXT('16U_M_Classic'!B41,"h:mm am/pm") -> 16BX-018-Group-10:20 AM | AS8: ='18U_M_INVITE_NEW_23'!L40&"-"&'18U_M_INVITE_NEW_23'!C40&"-"&TEXT('18U_M_INVITE_NEW_23'!B40,"h:mm am/pm") -> 18BQ-010-Group-10:20 AM | AT8: ='18U_M_INVITE_NEW_23'!L21&"-"&'18U_M_INVITE_NEW_23'!C21&"-"&TEXT('18U_M_INVITE_NEW_23'!B21,"h:mm am/pm") -> 18BQ-009-Group-10:20 AM | AU8: 0.43055556 | AV8: ='16U_M_Champ'!L22&"-"&'16U_M_Champ'!C22&"-"&TEXT('16U_M_Champ'!B22,"h:mm am/pm") -> 16B-017-Group-10:20 AM | AW8: ='16U_M_Champ'!L41&"-"&'16U_M_Champ'!C41&"-"&TEXT('16U_M_Champ'!B41,"h:mm am/pm") -> 16B-018-Group-10:20 AM | AX8: ='16U_M_Champ'!L60&"-"&'16U_M_Champ'!C60&"-"&TEXT('16U_M_Champ'!B60,"h:mm am/pm") -> 16B-019-Group-10:20 AM | AY8: ='16U_M_Champ'!L79&"-"&'16U_M_Champ'!C79&"-"&TEXT('16U_M_Champ'!B79,"h:mm am/pm") -> 16B-020-Group-10:20 AM | BA8: 0.45833333 | BB8: ='18U_M_Champ'!L22&"-"&'18U_M_Champ'!C22&"-"&TEXT('18U_M_Champ'!B22,"h:mm am/pm") -> 18B-021-Group-11:00 AM | BC8: ='18U_M_Champ'!L70&"-"&'18U_M_Champ'!C70&"-"&TEXT('18U_M_Champ'!B70,"h:mm am/pm") -> 18B-024-Group-11:00 AM | BD8: ='18U_M_Champ'!L38&"-"&'18U_M_Champ'!C38&"-"&TEXT('18U_M_Champ'!B38,"h:mm am/pm") -> 18B-022-Group-11:00 AM | BE8: ='18U_M_Champ'!L54&"-"&'18U_M_Champ'!C54&"-"&TEXT('18U_M_Champ'!B54,"h:mm am/pm") -> 18B-023-Group-11:00 AM | BF8: ='18U_M_Champ'!L86&"-"&'18U_M_Champ'!C86&"-"&TEXT('18U_M_Champ'!B86,"h:mm am/pm") -> 18B-025-Group-11:00 AM
A9: 0.46527778 | B9: ='10U_M_Champ_35'!L61&"-"&'10U_M_Champ_35'!C61&"-"&TEXT('10U_M_Champ_35'!B61,"h:mm am/pm") -> 10B-021-Group K-11:10 AM | C9: ='10U_M_Champ_35'!L21&"-"&'10U_M_Champ_35'!C21&"-"&TEXT('10U_M_Champ_35'!B21,"h:mm am/pm") -> 10B-016-Group B-11:10 AM | D9: ='10U_M_Champ_35'!L41&"-"&'10U_M_Champ_35'!C41&"-"&TEXT('10U_M_Champ_35'!B41,"h:mm am/pm") -> 10B-017-Group G-11:10 AM | E9: ='12U_M_Classic_53'!L73&"-"&'12U_M_Classic_53'!C73&"-"&TEXT('12U_M_Classic_53'!B73,"h:mm am/pm") -> 12BX-026-Group-11:10 AM | F9: ='12U_M_Classic_53'!L93&"-"&'12U_M_Classic_53'!C93&"-"&TEXT('12U_M_Classic_53'!B93,"h:mm am/pm") -> 12BX-032-Group-11:10 AM | G9: ='12U_M_Classic_53'!L113&"-"&'12U_M_Classic_53'!C113&"-"&TEXT('12U_M_Classic_53'!B113,"h:mm am/pm") -> 12BX-018-Group-11:10 AM | H9: ='12U_M_Classic_53'!L34&"-"&'12U_M_Classic_53'!C34&"-"&TEXT('12U_M_Classic_53'!B34,"h:mm am/pm") -> 12BX-043-Group-11:10 AM | I9: 0.46527778 | J9: ='12U_M_Classic_53'!L53&"-"&'12U_M_Classic_53'!C53&"-"&TEXT('12U_M_Classic_53'!B53,"h:mm am/pm") -> 12BX-025-Group-11:10 AM | K9: 0.46527778 | L9: ='12U_M_Champ'!L23&"-"&'12U_M_Champ'!C23&"-"&TEXT('12U_M_Champ'!B23,"h:mm am/pm") -> 12B-021-Group-11:10 AM | M9: ='12U_M_Champ'!L42&"-"&'12U_M_Champ'!C42&"-"&TEXT('12U_M_Champ'!B42,"h:mm am/pm") -> 12B-022-Group-11:10 AM | N9: ='12U_M_Champ'!L61&"-"&'12U_M_Champ'!C61&"-"&TEXT('12U_M_Champ'!B61,"h:mm am/pm") -> 12B-023-Group-11:10 AM | O9: ='12U_M_Champ'!L80&"-"&'12U_M_Champ'!C80&"-"&TEXT('12U_M_Champ'!B80,"h:mm am/pm") -> 12B-024-Group-11:10 AM | P9: 0.46527778 | Q9: ='14U_M_Champ'!L23&"-"&'14U_M_Champ'!C23&"-"&TEXT('14U_M_Champ'!B23,"h:mm am/pm") -> 14B-021-Group-11:10 AM | R9: ='14U_M_Champ'!L42&"-"&'14U_M_Champ'!C42&"-"&TEXT('14U_M_Champ'!B42,"h:mm am/pm") -> 14B-022-Group-11:10 AM | S9: ='14U_M_Champ'!L61&"-"&'14U_M_Champ'!C61&"-"&TEXT('14U_M_Champ'!B61,"h:mm am/pm") -> 14B-023-Group-11:10 AM | T9: ='14U_M_Champ'!L80&"-"&'14U_M_Champ'!C80&"-"&TEXT('14U_M_Champ'!B80,"h:mm am/pm") -> 14B-024-Group-11:10 AM | U9: ='14U_M_Invite_36'!L61&"-"&'14U_M_Invite_36'!C61&"-"&TEXT('14U_M_Invite_36'!B61,"h:mm am/pm") -> 14BQ-018-Group J-11:10 AM | V9: ='14U_M_Invite_36'!L41&"-"&'14U_M_Invite_36'!C41&"-"&TEXT('14U_M_Invite_36'!B41,"h:mm am/pm") -> 14BQ-017-Group G-11:10 AM | W9: ='14U_M_Invite_36'!L21&"-"&'14U_M_Invite_36'!C21&"-"&TEXT('14U_M_Invite_36'!B21,"h:mm am/pm") -> 14BQ-016-Group B-11:10 AM | X9: 0.46527778 | Z9: ='16U_M_Invite'!L88&"-"&'16U_M_Invite'!C88&"-"&TEXT('16U_M_Invite'!B88,"h:mm am/pm") -> 16BQ-024-Group-11:10 AM | AA9: ='14U_M_Classic'!L23&"-"&'14U_M_Classic'!C23&"-"&TEXT('14U_M_Classic'!B23,"h:mm am/pm") -> 14BX-024-Group-11:10 AM | AB9: ='14U_M_Classic'!L61&"-"&'14U_M_Classic'!C61&"-"&TEXT('14U_M_Classic'!B61,"h:mm am/pm") -> 14BX-022-Group-11:10 AM | AC9: ='14U_M_Classic'!L83&"-"&'14U_M_Classic'!C83&"-"&TEXT('14U_M_Classic'!B83,"h:mm am/pm") -> 14BX-021-Group-11:10 AM | AG9: ='18U_M_Classic'!L80&"-"&'18U_M_Classic'!C80&"-"&TEXT('18U_M_Classic'!B80,"h:mm am/pm") -> 18BX-024-Group-11:10 AM | AH9: ='18U_M_Classic'!L42&"-"&'18U_M_Classic'!C42&"-"&TEXT('18U_M_Classic'!B42,"h:mm am/pm") -> 18BX-022-Group-11:10 AM | AI9: ='18U_M_Classic'!L61&"-"&'18U_M_Classic'!C61&"-"&TEXT('18U_M_Classic'!B61,"h:mm am/pm") -> 18BX-023-Group-11:10 AM | AJ9: ='18U_M_Classic'!L23&"-"&'18U_M_Classic'!C23&"-"&TEXT('18U_M_Classic'!B23,"h:mm am/pm") -> 18BX-021-Group-11:10 AM | AK9: ='16U_M_Invite'!L50&"-"&'16U_M_Invite'!C50&"-"&TEXT('16U_M_Invite'!B50,"h:mm am/pm") -> 16BQ-022-Group-11:10 AM | AL9: ='14U_M_Classic'!L42&"-"&'14U_M_Classic'!C42&"-"&TEXT('14U_M_Classic'!B42,"h:mm am/pm") -> 14BX-023-Group-11:10 AM | AM9: ='16U_M_Invite'!L69&"-"&'16U_M_Invite'!C69&"-"&TEXT('16U_M_Invite'!B69,"h:mm am/pm") -> 16BQ-023-Group-11:10 AM | AN9: ='16U_M_Classic'!L61&"-"&'16U_M_Classic'!C61&"-"&TEXT('16U_M_Classic'!B61,"h:mm am/pm") -> 16BX-023-Group-11:10 AM | AO9: ='16U_M_Classic'!L80&"-"&'16U_M_Classic'!C80&"-"&TEXT('16U_M_Classic'!B80,"h:mm am/pm") -> 16BX-024-Group-11:10 AM | AP9: ='16U_M_Classic'!L23&"-"&'16U_M_Classic'!C23&"-"&TEXT('16U_M_Classic'!B23,"h:mm am/pm") -> 16BX-021-Group-11:10 AM | AQ9: ='16U_M_Classic'!L42&"-"&'16U_M_Classic'!C42&"-"&TEXT('16U_M_Classic'!B42,"h:mm am/pm") -> 16BX-022-Group-11:10 AM | AS9: ='18U_M_INVITE_NEW_23'!L41&"-"&'18U_M_INVITE_NEW_23'!C41&"-"&TEXT('18U_M_INVITE_NEW_23'!B41,"h:mm am/pm") -> 18BQ-012-Group-11:10 AM | AT9: ='18U_M_INVITE_NEW_23'!L22&"-"&'18U_M_INVITE_NEW_23'!C22&"-"&TEXT('18U_M_INVITE_NEW_23'!B22,"h:mm am/pm") -> 18BQ-011-Group-11:10 AM | AU9: 0.46527778 | AV9: ='16U_M_Champ'!L23&"-"&'16U_M_Champ'!C23&"-"&TEXT('16U_M_Champ'!B23,"h:mm am/pm") -> 16B-021-Group-11:10 AM | AW9: ='16U_M_Champ'!L42&"-"&'16U_M_Champ'!C42&"-"&TEXT('16U_M_Champ'!B42,"h:mm am/pm") -> 16B-022-Group-11:10 AM | AX9: ='16U_M_Champ'!L61&"-"&'16U_M_Champ'!C61&"-"&TEXT('16U_M_Champ'!B61,"h:mm am/pm") -> 16B-023-Group-11:10 AM | AY9: ='16U_M_Champ'!L80&"-"&'16U_M_Champ'!C80&"-"&TEXT('16U_M_Champ'!B80,"h:mm am/pm") -> 16B-024-Group-11:10 AM | BA9: 0.5 | BB9: ='18U_M_Champ'!L23&"-"&'18U_M_Champ'!C23&"-"&TEXT('18U_M_Champ'!B23,"h:mm am/pm") -> 18B-026-Group-12:00 PM | BC9: ='18U_M_Champ'!L55&"-"&'18U_M_Champ'!C55&"-"&TEXT('18U_M_Champ'!B55,"h:mm am/pm") -> 18B-029-Group-12:00 PM | BD9: ='18U_M_Champ'!L39&"-"&'18U_M_Champ'!C39&"-"&TEXT('18U_M_Champ'!B39,"h:mm am/pm") -> 18B-027-Group-12:00 PM | BE9: ='18U_M_Champ'!L71&"-"&'18U_M_Champ'!C71&"-"&TEXT('18U_M_Champ'!B71,"h:mm am/pm") -> 18B-028-Group-12:00 PM | BF9: ='18U_M_Champ'!L87&"-"&'18U_M_Champ'!C87&"-"&TEXT('18U_M_Champ'!B87,"h:mm am/pm") -> 18B-030-Group-12:00 PM
A10: 0.5 | B10: ='10U_M_Champ_35'!L62&"-"&'10U_M_Champ_35'!C62&"-"&TEXT('10U_M_Champ_35'!B62,"h:mm am/pm") -> 10B-024-Group L-12:00 PM | C10: ='10U_M_Champ_35'!L22&"-"&'10U_M_Champ_35'!C22&"-"&TEXT('10U_M_Champ_35'!B22,"h:mm am/pm") -> 10B-019-Group C-12:00 PM | D10: ='10U_M_Champ_35'!L42&"-"&'10U_M_Champ_35'!C42&"-"&TEXT('10U_M_Champ_35'!B42,"h:mm am/pm") -> 10B-020-Group F-12:00 PM | E10: ='12U_M_Classic_53'!L74&"-"&'12U_M_Classic_53'!C74&"-"&TEXT('12U_M_Classic_53'!B74,"h:mm am/pm") -> 12BX-031-Group-12:00 PM | F10: ='12U_M_Classic_53'!L94&"-"&'12U_M_Classic_53'!C94&"-"&TEXT('12U_M_Classic_53'!B94,"h:mm am/pm") -> 12BX-32A-Group-12:00 PM | G10: ='12U_M_Classic_53'!L114&"-"&'12U_M_Classic_53'!C114&"-"&TEXT('12U_M_Classic_53'!B114,"h:mm am/pm") -> 12BX-023-Group-12:00 PM | H10: ='12U_M_Classic_53'!L35&"-"&'12U_M_Classic_53'!C35&"-"&TEXT('12U_M_Classic_53'!B35,"h:mm am/pm") -> 12BX-029-Group-12:00 PM | I10: 0.5 | J10: ='12U_M_Classic_53'!L54&"-"&'12U_M_Classic_53'!C54&"-"&TEXT('12U_M_Classic_53'!B54,"h:mm am/pm") -> 12BX-030-Group-12:00 PM | K10: 0.5 | L10: ='12U_M_Champ'!L24&"-"&'12U_M_Champ'!C24&"-"&TEXT('12U_M_Champ'!B24,"h:mm am/pm") -> 12B-025-Group-12:00 PM | M10: ='12U_M_Champ'!L43&"-"&'12U_M_Champ'!C43&"-"&TEXT('12U_M_Champ'!B43,"h:mm am/pm") -> 12B-026-Group-12:00 PM | N10: ='12U_M_Champ'!L62&"-"&'12U_M_Champ'!C62&"-"&TEXT('12U_M_Champ'!B62,"h:mm am/pm") -> 12B-027-Group-12:00 PM | O10: ='12U_M_Champ'!L81&"-"&'12U_M_Champ'!C81&"-"&TEXT('12U_M_Champ'!B81,"h:mm am/pm") -> 12B-028-Group-12:00 PM | P10: 0.5 | Q10: ='14U_M_Champ'!L24&"-"&'14U_M_Champ'!C24&"-"&TEXT('14U_M_Champ'!B24,"h:mm am/pm") -> 14B-025-Group-12:00 PM | R10: ='14U_M_Champ'!L43&"-"&'14U_M_Champ'!C43&"-"&TEXT('14U_M_Champ'!B43,"h:mm am/pm") -> 14B-026-Group-12:00 PM | S10: ='14U_M_Champ'!L62&"-"&'14U_M_Champ'!C62&"-"&TEXT('14U_M_Champ'!B62,"h:mm am/pm") -> 14B-027-Group-12:00 PM | T10: ='14U_M_Champ'!L81&"-"&'14U_M_Champ'!C81&"-"&TEXT('14U_M_Champ'!B81,"h:mm am/pm") -> 14B-028-Group-12:00 PM | U10: ='14U_M_Invite_36'!L62&"-"&'14U_M_Invite_36'!C62&"-"&TEXT('14U_M_Invite_36'!B62,"h:mm am/pm") -> 14BQ-021-Group K-12:00 PM | V10: ='14U_M_Invite_36'!L42&"-"&'14U_M_Invite_36'!C42&"-"&TEXT('14U_M_Invite_36'!B42,"h:mm am/pm") -> 14BQ-020-Group F-12:00 PM | W10: ='14U_M_Invite_36'!L22&"-"&'14U_M_Invite_36'!C22&"-"&TEXT('14U_M_Invite_36'!B22,"h:mm am/pm") -> 14BQ-019-Group C-12:00 PM | X10: 0.5 | Z10: ='16U_M_Invite'!L89&"-"&'16U_M_Invite'!C89&"-"&TEXT('16U_M_Invite'!B89,"h:mm am/pm") -> 16BQ-028-Group-12:00 PM | AA10: ='14U_M_Classic'!L24&"-"&'14U_M_Classic'!C24&"-"&TEXT('14U_M_Classic'!B24,"h:mm am/pm") -> 14BX-028-Group-12:00 PM | AB10: ='14U_M_Classic'!L62&"-"&'14U_M_Classic'!C62&"-"&TEXT('14U_M_Classic'!B62,"h:mm am/pm") -> 14BX-026-Group-12:00 PM | AC10: ='14U_M_Classic'!L84&"-"&'14U_M_Classic'!C84&"-"&TEXT('14U_M_Classic'!B84,"h:mm am/pm") -> 14BX-025-Group-12:00 PM | AE10: ='16U_M_Invite'!L31&"-"&'16U_M_Invite'!C31&"-"&TEXT('16U_M_Invite'!B31,"h:mm am/pm") -> 16BQ-017-Group-12:30 PM | AG10: ='18U_M_Classic'!L81&"-"&'18U_M_Classic'!C81&"-"&TEXT('18U_M_Classic'!B81,"h:mm am/pm") -> 18BX-028-Group-12:00 PM | AH10: ='18U_M_Classic'!L43&"-"&'18U_M_Classic'!C43&"-"&TEXT('18U_M_Classic'!B43,"h:mm am/pm") -> 18BX-026-Group-12:00 PM | AI10: ='18U_M_Classic'!L62&"-"&'18U_M_Classic'!C62&"-"&TEXT('18U_M_Classic'!B62,"h:mm am/pm") -> 18BX-027-Group-12:00 PM | AJ10: ='18U_M_Classic'!L24&"-"&'18U_M_Classic'!C24&"-"&TEXT('18U_M_Classic'!B24,"h:mm am/pm") -> 18BX-025-Group-12:00 PM | AK10: ='16U_M_Invite'!L51&"-"&'16U_M_Invite'!C51&"-"&TEXT('16U_M_Invite'!B51,"h:mm am/pm") -> 16BQ-026-Group-12:00 PM | AL10: ='14U_M_Classic'!L43&"-"&'14U_M_Classic'!C43&"-"&TEXT('14U_M_Classic'!B43,"h:mm am/pm") -> 14BX-027-Group-12:00 PM | AM10: ='16U_M_Invite'!L70&"-"&'16U_M_Invite'!C70&"-"&TEXT('16U_M_Invite'!B70,"h:mm am/pm") -> 16BQ-027-Group-12:00 PM | AN10: ='16U_M_Classic'!L62&"-"&'16U_M_Classic'!C62&"-"&TEXT('16U_M_Classic'!B62,"h:mm am/pm") -> 16BX-027-Group-12:00 PM | AO10: ='16U_M_Classic'!L81&"-"&'16U_M_Classic'!C81&"-"&TEXT('16U_M_Classic'!B81,"h:mm am/pm") -> 16BX-028-Group-12:00 PM | AP10: ='16U_M_Classic'!L24&"-"&'16U_M_Classic'!C24&"-"&TEXT('16U_M_Classic'!B24,"h:mm am/pm") -> 16BX-025-Group-12:00 PM | AQ10: ='16U_M_Classic'!L43&"-"&'16U_M_Classic'!C43&"-"&TEXT('16U_M_Classic'!B43,"h:mm am/pm") -> 16BX-026-Group-12:00 PM | AT10: ='18U_M_INVITE_NEW_23'!L23&"-"&'18U_M_INVITE_NEW_23'!C23&"-"&TEXT('18U_M_INVITE_NEW_23'!B23,"h:mm am/pm") -> 18BQ-013-Group-12:00 PM | AU10: 0.5 | AV10: ='16U_M_Champ'!L24&"-"&'16U_M_Champ'!C24&"-"&TEXT('16U_M_Champ'!B24,"h:mm am/pm") -> 16B-025-Group-12:00 PM | AW10: ='16U_M_Champ'!L43&"-"&'16U_M_Champ'!C43&"-"&TEXT('16U_M_Champ'!B43,"h:mm am/pm") -> 16B-026-Group-12:00 PM | AX10: ='16U_M_Champ'!L62&"-"&'16U_M_Champ'!C62&"-"&TEXT('16U_M_Champ'!B62,"h:mm am/pm") -> 16B-027-Group-12:00 PM | AY10: ='16U_M_Champ'!L81&"-"&'16U_M_Champ'!C81&"-"&TEXT('16U_M_Champ'!B81,"h:mm am/pm") -> 16B-028-Group-12:00 PM | BA10: 0.54166667 | BB10: ='18U_M_Champ'!L24&"-"&'18U_M_Champ'!C24&"-"&TEXT('18U_M_Champ'!B24,"h:mm am/pm") -> 18B-031-Group-1:00 PM | BC10: ='18U_M_Champ'!L72&"-"&'18U_M_Champ'!C72&"-"&TEXT('18U_M_Champ'!B72,"h:mm am/pm") -> 18B-034-Group-1:00 PM | BD10: ='18U_M_Champ'!L40&"-"&'18U_M_Champ'!C40&"-"&TEXT('18U_M_Champ'!B40,"h:mm am/pm") -> 18B-032-Group-1:00 PM | BE10: ='18U_M_Champ'!L56&"-"&'18U_M_Champ'!C56&"-"&TEXT('18U_M_Champ'!B56,"h:mm am/pm") -> 18B-033-Group-1:00 PM | BF10: ='18U_M_Champ'!L88&"-"&'18U_M_Champ'!C88&"-"&TEXT('18U_M_Champ'!B88,"h:mm am/pm") -> 18B-035-Group-1:00 PM
A11: 0.53472222 | B11: ='10U_M_Champ_35'!L63&"-"&'10U_M_Champ_35'!C63&"-"&TEXT('10U_M_Champ_35'!B63,"h:mm am/pm") -> 10B-027-Group I-12:50 PM | C11: ='10U_M_Champ_35'!L23&"-"&'10U_M_Champ_35'!C23&"-"&TEXT('10U_M_Champ_35'!B23,"h:mm am/pm") -> 10B-022-Group D-12:50 PM | D11: ='10U_M_Champ_35'!L43&"-"&'10U_M_Champ_35'!C43&"-"&TEXT('10U_M_Champ_35'!B43,"h:mm am/pm") -> 10B-023-Group E-12:50 PM | E11: ='12U_M_Classic_53'!L75&"-"&'12U_M_Classic_53'!C75&"-"&TEXT('12U_M_Classic_53'!B75,"h:mm am/pm") -> 12BX-035-Group-12:50 PM | F11: ='12U_M_Classic_53'!L95&"-"&'12U_M_Classic_53'!C95&"-"&TEXT('12U_M_Classic_53'!B95,"h:mm am/pm") -> 12BX-036-Group-12:50 PM | G11: ='12U_M_Classic_53'!L115&"-"&'12U_M_Classic_53'!C115&"-"&TEXT('12U_M_Classic_53'!B115,"h:mm am/pm") -> 12BX-028-Group-12:50 PM | H11: ='12U_M_Classic_53'!L36&"-"&'12U_M_Classic_53'!C36&"-"&TEXT('12U_M_Classic_53'!B36,"h:mm am/pm") -> 12BX-034-Group-12:50 PM | I11: 0.53472222 | J11: ='12U_M_Classic_53'!L55&"-"&'12U_M_Classic_53'!C55&"-"&TEXT('12U_M_Classic_53'!B55,"h:mm am/pm") -> 12BX-038-Group-12:50 PM | K11: 0.53472222 | L11: ='12U_M_Champ'!L25&"-"&'12U_M_Champ'!C25&"-"&TEXT('12U_M_Champ'!B25,"h:mm am/pm") -> 12B-029-Group-12:50 PM | M11: ='12U_M_Champ'!L44&"-"&'12U_M_Champ'!C44&"-"&TEXT('12U_M_Champ'!B44,"h:mm am/pm") -> 12B-030-Group-12:50 PM | N11: ='12U_M_Champ'!L63&"-"&'12U_M_Champ'!C63&"-"&TEXT('12U_M_Champ'!B63,"h:mm am/pm") -> 12B-031-Group-12:50 PM | O11: ='12U_M_Champ'!L82&"-"&'12U_M_Champ'!C82&"-"&TEXT('12U_M_Champ'!B82,"h:mm am/pm") -> 12B-032-Group-12:50 PM | P11: 0.53472222 | Q11: ='14U_M_Champ'!L25&"-"&'14U_M_Champ'!C25&"-"&TEXT('14U_M_Champ'!B25,"h:mm am/pm") -> 14B-029-Group-12:50 PM | R11: ='14U_M_Champ'!L44&"-"&'14U_M_Champ'!C44&"-"&TEXT('14U_M_Champ'!B44,"h:mm am/pm") -> 14B-030-Group-12:50 PM | S11: ='14U_M_Champ'!L63&"-"&'14U_M_Champ'!C63&"-"&TEXT('14U_M_Champ'!B63,"h:mm am/pm") -> 14B-031-Group-12:50 PM | T11: ='14U_M_Champ'!L82&"-"&'14U_M_Champ'!C82&"-"&TEXT('14U_M_Champ'!B82,"h:mm am/pm") -> 14B-032-Group-12:50 PM | U11: ='14U_M_Invite_36'!L63&"-"&'14U_M_Invite_36'!C63&"-"&TEXT('14U_M_Invite_36'!B63,"h:mm am/pm") -> 14BQ-024-Group L-12:50 PM | V11: ='14U_M_Invite_36'!L43&"-"&'14U_M_Invite_36'!C43&"-"&TEXT('14U_M_Invite_36'!B43,"h:mm am/pm") -> 14BQ-023-Group E-12:50 PM | W11: ='14U_M_Invite_36'!L23&"-"&'14U_M_Invite_36'!C23&"-"&TEXT('14U_M_Invite_36'!B23,"h:mm am/pm") -> 14BQ-022-Group D-12:50 PM | X11: 0.53472222 | Z11: ='16U_M_Invite'!L90&"-"&'16U_M_Invite'!C90&"-"&TEXT('16U_M_Invite'!B90,"h:mm am/pm") -> 16BQ-032-Group-12:50 PM | AA11: ='14U_M_Classic'!L25&"-"&'14U_M_Classic'!C25&"-"&TEXT('14U_M_Classic'!B25,"h:mm am/pm") -> 14BX-032-Group-12:50 PM | AB11: ='14U_M_Classic'!L63&"-"&'14U_M_Classic'!C63&"-"&TEXT('14U_M_Classic'!B63,"h:mm am/pm") -> 14BX-030-Group-12:50 PM | AC11: ='14U_M_Classic'!L85&"-"&'14U_M_Classic'!C85&"-"&TEXT('14U_M_Classic'!B85,"h:mm am/pm") -> 14BX-029-Group-12:50 PM | AE11: ='16U_M_Invite'!L32&"-"&'16U_M_Invite'!C32&"-"&TEXT('16U_M_Invite'!B32,"h:mm am/pm") -> 16BQ-021-Group-1:20 PM | AG11: ='18U_M_Classic'!L82&"-"&'18U_M_Classic'!C82&"-"&TEXT('18U_M_Classic'!B82,"h:mm am/pm") -> 18BX-032-Group-12:50 PM | AH11: ='18U_M_Classic'!L44&"-"&'18U_M_Classic'!C44&"-"&TEXT('18U_M_Classic'!B44,"h:mm am/pm") -> 18BX-030-Group-12:50 PM | AI11: ='18U_M_Classic'!L63&"-"&'18U_M_Classic'!C63&"-"&TEXT('18U_M_Classic'!B63,"h:mm am/pm") -> 18BX-031-Group-12:50 PM | AJ11: ='18U_M_Classic'!L25&"-"&'18U_M_Classic'!C25&"-"&TEXT('18U_M_Classic'!B25,"h:mm am/pm") -> 18BX-029-Group-12:50 PM | AK11: ='16U_M_Invite'!L52&"-"&'16U_M_Invite'!C52&"-"&TEXT('16U_M_Invite'!B52,"h:mm am/pm") -> 16BQ-030-Group-12:50 PM | AL11: ='14U_M_Classic'!L44&"-"&'14U_M_Classic'!C44&"-"&TEXT('14U_M_Classic'!B44,"h:mm am/pm") -> 14BX-031-Group-12:50 PM | AM11: ='16U_M_Invite'!L71&"-"&'16U_M_Invite'!C71&"-"&TEXT('16U_M_Invite'!B71,"h:mm am/pm") -> 16BQ-031-Group-12:50 PM | AN11: ='16U_M_Classic'!L63&"-"&'16U_M_Classic'!C63&"-"&TEXT('16U_M_Classic'!B63,"h:mm am/pm") -> 16BX-031-Group-12:50 PM | AO11: ='16U_M_Classic'!L82&"-"&'16U_M_Classic'!C82&"-"&TEXT('16U_M_Classic'!B82,"h:mm am/pm") -> 16BX-032-Group-12:50 PM | AP11: ='16U_M_Classic'!L25&"-"&'16U_M_Classic'!C25&"-"&TEXT('16U_M_Classic'!B25,"h:mm am/pm") -> 16BX-029-Group-12:50 PM | AQ11: ='16U_M_Classic'!L44&"-"&'16U_M_Classic'!C44&"-"&TEXT('16U_M_Classic'!B44,"h:mm am/pm") -> 16BX-030-Group-12:50 PM | AR11: ='18U_M_INVITE_NEW_23'!L45&"-"&'18U_M_INVITE_NEW_23'!C45&"-"&TEXT('18U_M_INVITE_NEW_23'!B45,"h:mm am/pm") -> 18BQ-014-Group-1:00 PM | AT11: ='18U_M_INVITE_NEW_23'!L24&"-"&'18U_M_INVITE_NEW_23'!C24&"-"&TEXT('18U_M_INVITE_NEW_23'!B24,"h:mm am/pm") -> 18BQ-015-Group-12:50 PM | AU11: 0.53472222 | AV11: ='16U_M_Champ'!L25&"-"&'16U_M_Champ'!C25&"-"&TEXT('16U_M_Champ'!B25,"h:mm am/pm") -> 16B-029-Group-12:50 PM | AW11: ='16U_M_Champ'!L44&"-"&'16U_M_Champ'!C44&"-"&TEXT('16U_M_Champ'!B44,"h:mm am/pm") -> 16B-030-Group-12:50 PM | AX11: ='16U_M_Champ'!L63&"-"&'16U_M_Champ'!C63&"-"&TEXT('16U_M_Champ'!B63,"h:mm am/pm") -> 16B-031-Group-12:50 PM | AY11: ='16U_M_Champ'!L82&"-"&'16U_M_Champ'!C82&"-"&TEXT('16U_M_Champ'!B82,"h:mm am/pm") -> 16B-032-Group-12:50 PM | BA11: 0.58333333 | BB11: ='18U_M_Champ'!L25&"-"&'18U_M_Champ'!C25&"-"&TEXT('18U_M_Champ'!B25,"h:mm am/pm") -> 18B-036-Group-2:00 PM | BC11: ='18U_M_Champ'!L73&"-"&'18U_M_Champ'!C73&"-"&TEXT('18U_M_Champ'!B73,"h:mm am/pm") -> 18B-039-Group-2:00 PM | BD11: ='18U_M_Champ'!L41&"-"&'18U_M_Champ'!C41&"-"&TEXT('18U_M_Champ'!B41,"h:mm am/pm") -> 18B-037-Group-2:00 PM | BE11: ='18U_M_Champ'!L57&"-"&'18U_M_Champ'!C57&"-"&TEXT('18U_M_Champ'!B57,"h:mm am/pm") -> 18B-038-Group-2:00 PM | BF11: ='18U_M_Champ'!L89&"-"&'18U_M_Champ'!C89&"-"&TEXT('18U_M_Champ'!B89,"h:mm am/pm") -> 18B-040-Group-2:00 PM
A12: 0.56944444 | B12: ='10U_M_Champ_35'!L64&"-"&'10U_M_Champ_35'!C64&"-"&TEXT('10U_M_Champ_35'!B64,"h:mm am/pm") -> 10B-030-Group J-1:40 PM | C12: ='10U_M_Champ_35'!L24&"-"&'10U_M_Champ_35'!C24&"-"&TEXT('10U_M_Champ_35'!B24,"h:mm am/pm") -> 10B-025-Group A-1:40 PM | D12: ='10U_M_Champ_35'!L44&"-"&'10U_M_Champ_35'!C44&"-"&TEXT('10U_M_Champ_35'!B44,"h:mm am/pm") -> 10B-026-Group H-1:40 PM | E12: ='12U_M_Classic_53'!L76&"-"&'12U_M_Classic_53'!C76&"-"&TEXT('12U_M_Classic_53'!B76,"h:mm am/pm") -> 12BX-040-Group-1:40 PM | F12: ='12U_M_Classic_53'!L96&"-"&'12U_M_Classic_53'!C96&"-"&TEXT('12U_M_Classic_53'!B96,"h:mm am/pm") -> 12BX-041-Group-1:40 PM | G12: ='12U_M_Classic_53'!L116&"-"&'12U_M_Classic_53'!C116&"-"&TEXT('12U_M_Classic_53'!B116,"h:mm am/pm") -> 12BX-033-Group-1:40 PM | H12: ='12U_M_Classic_53'!L37&"-"&'12U_M_Classic_53'!C37&"-"&TEXT('12U_M_Classic_53'!B37,"h:mm am/pm") -> 12BX-53A-Group-1:40 PM | I12: 0.56944444 | J12: ='12U_M_Classic_53'!L56&"-"&'12U_M_Classic_53'!C56&"-"&TEXT('12U_M_Classic_53'!B56,"h:mm am/pm") -> 12BX-039-Group-1:40 PM | K12: 0.56944444 | L12: ='12U_M_Champ'!L26&"-"&'12U_M_Champ'!C26&"-"&TEXT('12U_M_Champ'!B26,"h:mm am/pm") -> 12B-033-Group-1:40 PM | M12: ='12U_M_Champ'!L45&"-"&'12U_M_Champ'!C45&"-"&TEXT('12U_M_Champ'!B45,"h:mm am/pm") -> 12B-034-Group-1:40 PM | N12: ='12U_M_Champ'!L64&"-"&'12U_M_Champ'!C64&"-"&TEXT('12U_M_Champ'!B64,"h:mm am/pm") -> 12B-035-Group-1:40 PM | O12: ='12U_M_Champ'!L83&"-"&'12U_M_Champ'!C83&"-"&TEXT('12U_M_Champ'!B83,"h:mm am/pm") -> 12B-036-Group-1:40 PM | P12: 0.56944444 | Q12: ='14U_M_Champ'!L26&"-"&'14U_M_Champ'!C26&"-"&TEXT('14U_M_Champ'!B26,"h:mm am/pm") -> 14B-033-Group-1:40 PM | R12: ='14U_M_Champ'!L45&"-"&'14U_M_Champ'!C45&"-"&TEXT('14U_M_Champ'!B45,"h:mm am/pm") -> 14B-034-Group-1:40 PM | S12: ='14U_M_Champ'!L64&"-"&'14U_M_Champ'!C64&"-"&TEXT('14U_M_Champ'!B64,"h:mm am/pm") -> 14B-035-Group-1:40 PM | T12: ='14U_M_Champ'!L83&"-"&'14U_M_Champ'!C83&"-"&TEXT('14U_M_Champ'!B83,"h:mm am/pm") -> 14B-036-Group-1:40 PM | U12: ='14U_M_Invite_36'!L64&"-"&'14U_M_Invite_36'!C64&"-"&TEXT('14U_M_Invite_36'!B64,"h:mm am/pm") -> 14BQ-027-Group I-1:40 PM | V12: ='14U_M_Invite_36'!L44&"-"&'14U_M_Invite_36'!C44&"-"&TEXT('14U_M_Invite_36'!B44,"h:mm am/pm") -> 14BQ-026-Group H-1:40 PM | W12: ='14U_M_Invite_36'!L24&"-"&'14U_M_Invite_36'!C24&"-"&TEXT('14U_M_Invite_36'!B24,"h:mm am/pm") -> 14BQ-025-Group A-1:40 PM | X12: 0.56944444 | Z12: ='16U_M_Invite'!L91&"-"&'16U_M_Invite'!C91&"-"&TEXT('16U_M_Invite'!B91,"h:mm am/pm") -> 16BQ-036-Group-1:40 PM | AA12: ='14U_M_Classic'!L26&"-"&'14U_M_Classic'!C26&"-"&TEXT('14U_M_Classic'!B26,"h:mm am/pm") -> 14BX-036-Group-1:40 PM | AB12: ='14U_M_Classic'!L64&"-"&'14U_M_Classic'!C64&"-"&TEXT('14U_M_Classic'!B64,"h:mm am/pm") -> 14BX-034-Group-1:40 PM | AC12: ='14U_M_Classic'!L86&"-"&'14U_M_Classic'!C86&"-"&TEXT('14U_M_Classic'!B86,"h:mm am/pm") -> 14BX-033-Group-1:40 PM | AE12: ='16U_M_Invite'!L33&"-"&'16U_M_Invite'!C33&"-"&TEXT('16U_M_Invite'!B33,"h:mm am/pm") -> 16BQ-025-Group-2:10 PM | AG12: ='18U_M_Classic'!L83&"-"&'18U_M_Classic'!C83&"-"&TEXT('18U_M_Classic'!B83,"h:mm am/pm") -> 18BX-036-Group-1:40 PM | AH12: ='18U_M_Classic'!L45&"-"&'18U_M_Classic'!C45&"-"&TEXT('18U_M_Classic'!B45,"h:mm am/pm") -> 18BX-034-Group-1:40 PM | AI12: ='18U_M_Classic'!L64&"-"&'18U_M_Classic'!C64&"-"&TEXT('18U_M_Classic'!B64,"h:mm am/pm") -> 18BX-035-Group-1:40 PM | AJ12: ='18U_M_Classic'!L26&"-"&'18U_M_Classic'!C26&"-"&TEXT('18U_M_Classic'!B26,"h:mm am/pm") -> 18BX-033-Group-1:40 PM | AK12: ='16U_M_Invite'!L53&"-"&'16U_M_Invite'!C53&"-"&TEXT('16U_M_Invite'!B53,"h:mm am/pm") -> 16BQ-034-Group-1:40 PM | AL12: ='14U_M_Classic'!L45&"-"&'14U_M_Classic'!C45&"-"&TEXT('14U_M_Classic'!B45,"h:mm am/pm") -> 14BX-035-Group-1:40 PM | AM12: ='16U_M_Invite'!L72&"-"&'16U_M_Invite'!C72&"-"&TEXT('16U_M_Invite'!B72,"h:mm am/pm") -> 16BQ-035-Group-1:40 PM | AN12: ='16U_M_Classic'!L64&"-"&'16U_M_Classic'!C64&"-"&TEXT('16U_M_Classic'!B64,"h:mm am/pm") -> 16BX-035-Group-1:40 PM | AO12: ='16U_M_Classic'!L83&"-"&'16U_M_Classic'!C83&"-"&TEXT('16U_M_Classic'!B83,"h:mm am/pm") -> 16BX-036-Group-1:40 PM | AP12: ='16U_M_Classic'!L26&"-"&'16U_M_Classic'!C26&"-"&TEXT('16U_M_Classic'!B26,"h:mm am/pm") -> 16BX-033-Group-1:40 PM | AQ12: ='16U_M_Classic'!L45&"-"&'16U_M_Classic'!C45&"-"&TEXT('16U_M_Classic'!B45,"h:mm am/pm") -> 16BX-034-Group-1:40 PM | AR12: ='18U_M_INVITE_NEW_23'!L46&"-"&'18U_M_INVITE_NEW_23'!C46&"-"&TEXT('18U_M_INVITE_NEW_23'!B46,"h:mm am/pm") -> 18BQ-016-Group-1:50 PM | AT12: ='18U_M_INVITE_NEW_23'!L25&"-"&'18U_M_INVITE_NEW_23'!C25&"-"&TEXT('18U_M_INVITE_NEW_23'!B25,"h:mm am/pm") -> 18BQ-017-Group-1:40 PM | AU12: 0.56944444 | AV12: ='16U_M_Champ'!L26&"-"&'16U_M_Champ'!C26&"-"&TEXT('16U_M_Champ'!B26,"h:mm am/pm") -> 16B-033-Group-1:40 PM | AW12: ='16U_M_Champ'!L45&"-"&'16U_M_Champ'!C45&"-"&TEXT('16U_M_Champ'!B45,"h:mm am/pm") -> 16B-034-Group-1:40 PM | AX12: ='16U_M_Champ'!L64&"-"&'16U_M_Champ'!C64&"-"&TEXT('16U_M_Champ'!B64,"h:mm am/pm") -> 16B-035-Group-1:40 PM | AY12: ='16U_M_Champ'!L83&"-"&'16U_M_Champ'!C83&"-"&TEXT('16U_M_Champ'!B83,"h:mm am/pm") -> 16B-036-Group-1:40 PM | BA12: 0.625 | BB12: ='18U_M_Champ'!L26&"-"&'18U_M_Champ'!C26&"-"&TEXT('18U_M_Champ'!B26,"h:mm am/pm") -> 18B-041-Group-3:00 PM | BC12: ='18U_M_Champ'!L74&"-"&'18U_M_Champ'!C74&"-"&TEXT('18U_M_Champ'!B74,"h:mm am/pm") -> 18B-044-Group-3:00 PM | BD12: ='18U_M_Champ'!L42&"-"&'18U_M_Champ'!C42&"-"&TEXT('18U_M_Champ'!B42,"h:mm am/pm") -> 18B-042-Group-3:00 PM | BE12: ='18U_M_Champ'!L58&"-"&'18U_M_Champ'!C58&"-"&TEXT('18U_M_Champ'!B58,"h:mm am/pm") -> 18B-043-Group-3:00 PM
A13: 0.60416667 | B13: ='10U_M_Champ_35'!L65&"-"&'10U_M_Champ_35'!C65&"-"&TEXT('10U_M_Champ_35'!B65,"h:mm am/pm") -> 10B-036-Group L-2:30 PM | C13: ='10U_M_Champ_35'!L25&"-"&'10U_M_Champ_35'!C25&"-"&TEXT('10U_M_Champ_35'!B25,"h:mm am/pm") -> 10B-028-Group B-2:30 PM | D13: ='10U_M_Champ_35'!L45&"-"&'10U_M_Champ_35'!C45&"-"&TEXT('10U_M_Champ_35'!B45,"h:mm am/pm") -> 10B-029-Group G-2:30 PM | E13: ='12U_M_Classic_53'!L77&"-"&'12U_M_Classic_53'!C77&"-"&TEXT('12U_M_Classic_53'!B77,"h:mm am/pm") -> 12BX-045-Group-2:30 PM | F13: ='12U_M_Classic_53'!L97&"-"&'12U_M_Classic_53'!C97&"-"&TEXT('12U_M_Classic_53'!B97,"h:mm am/pm") -> 12BX-046-Group-2:30 PM | G13: ='12U_M_Classic_53'!L117&"-"&'12U_M_Classic_53'!C117&"-"&TEXT('12U_M_Classic_53'!B117,"h:mm am/pm") -> 12BX-037-Group-2:30 PM | H13: ='12U_M_Classic_53'!L38&"-"&'12U_M_Classic_53'!C38&"-"&TEXT('12U_M_Classic_53'!B38,"h:mm am/pm") -> 12BX-53B-Group-2:30 PM | I13: 0.60416667 | J13: ='12U_M_Classic_53'!L57&"-"&'12U_M_Classic_53'!C57&"-"&TEXT('12U_M_Classic_53'!B57,"h:mm am/pm") -> 12BX-044-Group-2:30 PM | K13: 0.60416667 | L13: ='12U_M_Champ'!L27&"-"&'12U_M_Champ'!C27&"-"&TEXT('12U_M_Champ'!B27,"h:mm am/pm") -> 12B-037-Group-2:30 PM | M13: ='12U_M_Champ'!L46&"-"&'12U_M_Champ'!C46&"-"&TEXT('12U_M_Champ'!B46,"h:mm am/pm") -> 12B-038-Group-2:30 PM | N13: ='12U_M_Champ'!L65&"-"&'12U_M_Champ'!C65&"-"&TEXT('12U_M_Champ'!B65,"h:mm am/pm") -> 12B-039-Group-2:30 PM | O13: ='12U_M_Champ'!L84&"-"&'12U_M_Champ'!C84&"-"&TEXT('12U_M_Champ'!B84,"h:mm am/pm") -> 12B-040-Group-2:30 PM | P13: 0.60416667 | Q13: ='14U_M_Champ'!L27&"-"&'14U_M_Champ'!C27&"-"&TEXT('14U_M_Champ'!B27,"h:mm am/pm") -> 14B-037-Group-2:30 PM | R13: ='14U_M_Champ'!L46&"-"&'14U_M_Champ'!C46&"-"&TEXT('14U_M_Champ'!B46,"h:mm am/pm") -> 14B-038-Group-2:30 PM | S13: ='14U_M_Champ'!L65&"-"&'14U_M_Champ'!C65&"-"&TEXT('14U_M_Champ'!B65,"h:mm am/pm") -> 14B-039-Group-2:30 PM | T13: ='14U_M_Champ'!L84&"-"&'14U_M_Champ'!C84&"-"&TEXT('14U_M_Champ'!B84,"h:mm am/pm") -> 14B-040-Group-2:30 PM | U13: ='14U_M_Invite_36'!L65&"-"&'14U_M_Invite_36'!C65&"-"&TEXT('14U_M_Invite_36'!B65,"h:mm am/pm") -> 14BQ-030-Group J-2:30 PM | V13: ='14U_M_Invite_36'!L45&"-"&'14U_M_Invite_36'!C45&"-"&TEXT('14U_M_Invite_36'!B45,"h:mm am/pm") -> 14BQ-029-Group G-2:30 PM | W13: ='14U_M_Invite_36'!L25&"-"&'14U_M_Invite_36'!C25&"-"&TEXT('14U_M_Invite_36'!B25,"h:mm am/pm") -> 14BQ-028-Group B-2:30 PM | X13: 0.60416667 | Z13: ='16U_M_Invite'!L92&"-"&'16U_M_Invite'!C92&"-"&TEXT('16U_M_Invite'!B92,"h:mm am/pm") -> 16BQ-040-Group-2:30 PM | AA13: ='14U_M_Classic'!L27&"-"&'14U_M_Classic'!C27&"-"&TEXT('14U_M_Classic'!B27,"h:mm am/pm") -> 14BX-040-Group-2:30 PM | AB13: ='14U_M_Classic'!L65&"-"&'14U_M_Classic'!C65&"-"&TEXT('14U_M_Classic'!B65,"h:mm am/pm") -> 14BX-038-Group-2:30 PM | AC13: ='14U_M_Classic'!L87&"-"&'14U_M_Classic'!C87&"-"&TEXT('14U_M_Classic'!B87,"h:mm am/pm") -> 14BX-037-Group-2:30 PM | AE13: ='16U_M_Invite'!L34&"-"&'16U_M_Invite'!C34&"-"&TEXT('16U_M_Invite'!B34,"h:mm am/pm") -> 16BQ-029-Group-3:00 PM | AG13: ='18U_M_Classic'!L84&"-"&'18U_M_Classic'!C84&"-"&TEXT('18U_M_Classic'!B84,"h:mm am/pm") -> 18BX-040-Group-2:30 PM | AH13: ='18U_M_Classic'!L46&"-"&'18U_M_Classic'!C46&"-"&TEXT('18U_M_Classic'!B46,"h:mm am/pm") -> 18BX-038-Group-2:30 PM | AI13: ='18U_M_Classic'!L65&"-"&'18U_M_Classic'!C65&"-"&TEXT('18U_M_Classic'!B65,"h:mm am/pm") -> 18BX-039-Group-2:30 PM | AJ13: ='18U_M_Classic'!L27&"-"&'18U_M_Classic'!C27&"-"&TEXT('18U_M_Classic'!B27,"h:mm am/pm") -> 18BX-037-Group-2:30 PM | AK13: ='16U_M_Invite'!L54&"-"&'16U_M_Invite'!C54&"-"&TEXT('16U_M_Invite'!B54,"h:mm am/pm") -> 16BQ-038-Group-2:30 PM | AL13: ='14U_M_Classic'!L46&"-"&'14U_M_Classic'!C46&"-"&TEXT('14U_M_Classic'!B46,"h:mm am/pm") -> 14BX-039-Group-2:30 PM | AM13: ='16U_M_Invite'!L73&"-"&'16U_M_Invite'!C73&"-"&TEXT('16U_M_Invite'!B73,"h:mm am/pm") -> 16BQ-039-Group-2:30 PM | AN13: ='16U_M_Classic'!L65&"-"&'16U_M_Classic'!C65&"-"&TEXT('16U_M_Classic'!B65,"h:mm am/pm") -> 16BX-039-Group-2:30 PM | AO13: ='16U_M_Classic'!L84&"-"&'16U_M_Classic'!C84&"-"&TEXT('16U_M_Classic'!B84,"h:mm am/pm") -> 16BX-040-Group-2:30 PM | AP13: ='16U_M_Classic'!L27&"-"&'16U_M_Classic'!C27&"-"&TEXT('16U_M_Classic'!B27,"h:mm am/pm") -> 16BX-037-Group-2:30 PM | AQ13: ='16U_M_Classic'!L46&"-"&'16U_M_Classic'!C46&"-"&TEXT('16U_M_Classic'!B46,"h:mm am/pm") -> 16BX-038-Group-2:30 PM | AR13: ='18U_M_INVITE_NEW_23'!L47&"-"&'18U_M_INVITE_NEW_23'!C47&"-"&TEXT('18U_M_INVITE_NEW_23'!B47,"h:mm am/pm") -> 18BQ-018-Group-2:40 PM | AT13: ='18U_M_INVITE_NEW_23'!L26&"-"&'18U_M_INVITE_NEW_23'!C26&"-"&TEXT('18U_M_INVITE_NEW_23'!B26,"h:mm am/pm") -> 18BQ-019-Group-2:30 PM | AU13: 0.60416667 | AV13: ='16U_M_Champ'!L27&"-"&'16U_M_Champ'!C27&"-"&TEXT('16U_M_Champ'!B27,"h:mm am/pm") -> 16B-037-Group-2:30 PM | AW13: ='16U_M_Champ'!L46&"-"&'16U_M_Champ'!C46&"-"&TEXT('16U_M_Champ'!B46,"h:mm am/pm") -> 16B-038-Group-2:30 PM | AX13: ='16U_M_Champ'!L65&"-"&'16U_M_Champ'!C65&"-"&TEXT('16U_M_Champ'!B65,"h:mm am/pm") -> 16B-039-Group-2:30 PM | AY13: ='16U_M_Champ'!L84&"-"&'16U_M_Champ'!C84&"-"&TEXT('16U_M_Champ'!B84,"h:mm am/pm") -> 16B-040-Group-2:30 PM | BA13: 0.66666667 | BB13: ='18U_M_Champ'!L27&"-"&'18U_M_Champ'!C27&"-"&TEXT('18U_M_Champ'!B27,"h:mm am/pm") -> 18B-045-Group-4:00 PM | BC13: ='18U_M_Champ'!L75&"-"&'18U_M_Champ'!C75&"-"&TEXT('18U_M_Champ'!B75,"h:mm am/pm") -> 18B-048-Group-4:00 PM | BD13: ='18U_M_Champ'!L43&"-"&'18U_M_Champ'!C43&"-"&TEXT('18U_M_Champ'!B43,"h:mm am/pm") -> 18B-046-Group-4:00 PM | BE13: ='18U_M_Champ'!L59&"-"&'18U_M_Champ'!C59&"-"&TEXT('18U_M_Champ'!B59,"h:mm am/pm") -> 18B-047-Group-4:00 PM | BF13: ='18U_M_Champ'!L91&"-"&'18U_M_Champ'!C91&"-"&TEXT('18U_M_Champ'!B91,"h:mm am/pm") -> 18B-049-2-3 cross-4:00 PM
